Workbook

Sheet Start Here
B1: 💎 DFS Card Grader — Business Operations Kit
B2: A complete operating system for running a profitable sports card business
B4: 👋 WELCOME
B5: Whether you're just starting out or scaling an existing card business, this workbook gives you the same tools and systems used by serious collectors and resellers.
B6: It works hand-in-hand with the DFS Card Grader app — use the app to research cards and make grading decisions, then use this workbook to plan, track, and grow your business.
B7: Every tab has a job. Work through the Getting Started checklist below, fill in your numbers, and the workbook will start giving you real answers about your business.
B9: 🎯 STEP 1 — SET YOUR MONTHLY REVENUE GOAL
B10: ▸ What is your monthly revenue goal? | C10: Go to the Path to $40k tab → enter your target in the yellow input cell. The model will calculate how many cards you need to sell per day, at what average price, to hit it.
B11: ▸ What is your average card value? | C11: Look at your last 10–20 sales. What did they sell for on average? Enter this in the Path to $40k assumptions. Lower avg price = more volume needed.
B12: ▸ What margin are you targeting?
B13: ▸ How much capital do you have to work with? | C13: Enter your starting capital in the Capital Velocity tab. It will show you how many times you need to flip that capital per month to hit your revenue goal.
B15: 📦 STEP 2 — KNOW YOUR INVENTORY
B16: ▸ Log every card you own | C16: Use the Inventory & Aging tab. Enter the card, what you paid (cost basis), where it's listed, and the asking price. This is your business balance sheet.
B17: ▸ Watch the aging flags | C17: Any card listed 30+ days with no sale is a problem. The Inventory & Aging tab flags these automatically. Use the Stale Action Plan tab to decide what to do — drop price, relist, or consign.
B18: ▸ Know what's costing you money
B19: ▸ Build your buy list | C19: The Target Card List tab is where you track what to buy next. Set a Max Buy price and a Target Sell price before you buy anything — never buy without a plan.
B21: 💎 STEP 3 — USE GRADING AS A REVENUE LEVER
B22: ▸ Not every card is worth grading | C22: Only grade cards where: (1) the gem rate is 40%+, and (2) a PSA 10 sells for at least 4× your raw cost after fees. Use the Grading ROI Calculator tab to run the numbers before you submit anything.
B23: ▸ Search first in the app | C23: Open the DFS Card Grader app → search the card → get the gem rate from GemRate.com → enter the PSA 10 market value → the app tells you GO or NO-GO instantly.
B24: ▸ Log every submission | C24: Use the Grading Tracker tab to log every card you send to PSA — tier, fee, expected price, and target. When grades come back, update the actual results to track your real grading ROI over time.
B25: ▸ Build a grading pipeline
B27: 💰 STEP 4 — SELL SMARTER ACROSS CHANNELS
B28: ▸ Not all channels are equal | C28: eBay, HeyStack, COMC, Whatnot, and consignment houses all have different fees and buyer pools. The Channel Fees tab shows your net payout at each price point so you route the right card to the right platform.
B29: ▸ Log every sale immediately | C29: Use the Sales Log tab. Date, card, channel, sell price, fees, and net. This is your income statement. Review it weekly — your data will show you which channels and card types make you the most money.
B30: ▸ Use consignment for high-value cards | C30: Cards over $100–200 often do better at auction houses like DcSports87, PWCC, or Probstein. Track every consignment in the Consignment Tracker tab — submission date, estimated value, and when to expect payment.
B31: ▸ HeyStack priority scoring
B33: ✅ GETTING STARTED CHECKLIST
B34: ☐ | C34: Set your monthly revenue goal in the Path to $40k tab
B35: ☐ | C35: Enter your starting capital in the Capital Velocity tab
B36: ☐
B37: ☐ | C37: Build your buy list in the Target Card List tab
B38: ☐ | C38: Review the Channel Fees tab and understand your platform costs
B39: ☐ | C39: Search your first card in the DFS Card Grader app and get a GO/NO-GO
B40: ☐ | C40: Add your first grading candidate to the Grading Candidates tab
B41: ☐ | C41: Log your next sale in the Sales Log the day it sells
B42: ☐ | C42: Check Inventory & Aging weekly — flag anything listed 30+ days
B43: ☐
B45: 📑 TAB DIRECTORY
B46: 💎 GRADING TOOLS
B47: ➤ PSA Fee Schedule | C47: All 7 PSA tiers — fees, turnaround times, and eBay cost breakdown
...

Sheet Dashboard
A1: 🏠 Start Here
A2: Your weekly 60-second check-in. Numbers pull from the other tabs.
A4: HEADLINE NUMBERS (from live data)
B5: Direct Sales Gross | D5: Direct Sales Net | F5: Consignment Net | H5: Total Net (all channels)
B6: ='Sales Log'!F3 -> 128 | D6: ='Sales Log'!J3 -> 44.78 | F6: ='Consignment Tracker'!I3 -> 0 | H6: ='Sales Log'!J3+'Consignment Tracker'!I3 -> 44.78
B8: Direct Margin % | D8: Avg Net / Consigned Card | F8: Stale Cards (≥60d) | H8: Capital at Risk (stale)
B9: =IFERROR('Sales Log'!J3/'Sales Log'!F3,"") -> 0.34984375 | D9: =IFERROR('Consignment Tracker'!I3/'Consignment Tracker'!C3,"") | F9: ='Inventory & Aging'!E3 -> 0 | H9: ='Inventory & Aging'!G3 -> 0
A12: PROGRESS vs TARGETS
B13: Monthly Net Target (current phase) | E13: 8000
B14: Actual Monthly Net (YTD-indicative) | E14: ='Sales Log'!J3+'Consignment Tracker'!I3 -> 44.78
B15: % of Phase Target | E15: =IFERROR(C14/C13,"")
A18: QUICK ACTIONS
B19: → Sales Log: log any sales since last week.
B20: → Consignment Tracker: update any auctions that closed.
B21: → Inventory & Aging: route all STALE-flagged cards to next consignment batch.
B22: → Path to $40k: compare actual net vs this month's milestone.
B23: → Helper ROI: if you haven't hired yet, re-run the calculator — it is the fastest win.

Sheet Target Card List
A1: 🏠 Start Here
A2: 25 NFL + 20 Soccer + 20 Baseball (liquid ≥10 sales/90d) — $8-155 band. WC 2026 LIVE in 6 weeks. 2025 MLB season catalyst active.
E3: TOTALS → | F3: =SUM(F5:F55) -> 73 | G3: =SUM(G5:G55) -> 180 | H3: =SUM(H5:H55) -> 281.4 | I3: =SUM(I5:I55) -> -174.4 | L3: =IFERROR(I3/G3,"") -> -0.96888889
A4: # | B4: Sport | C4: Player | D4: Card / Variant | E4: Grade / Cond. | F4: Max Buy ($) | G4: Target Sell ($) | H4: Est. Fees ($) | I4: Est. Net ($) | J4: Catalyst / Why | K4: Best Channel | L4: Margin % | M4: In Stock | N4: Your Avg $ | O4: Status
A5: 1 | B5: NFL | C5: Patrick Mahomes | D5: 2017 Panini Prizm #269 RC Silver | E5: Raw NM-M | F5: 35 | G5: 80 | H5: =G5*0.1325 -> 10.6 | I5: =G5-H5-F5 -> 34.4 | J5: SB contender, top QB | K5: eBay BIN | L5: =IFERROR(I5/G5,"") -> 0.43
A6: 2 | B6: NFL | C6: Ja'Marr Chase | D6: 2021 Panini Prizm #387 RC Silver | E6: Raw NM-M | F6: 20 | G6: 55 | H6: =G6*0.1325 -> 7.2875 | I6: =G6-H6-F6 -> 27.7125 | J6: WR1 threat | K6: eBay BIN | L6: =IFERROR(I6/G6,"") -> 0.50386364
A7: 3 | B7: MLB | C7: Juan Soto | D7: 2018 Topps Chrome #31 RC | E7: Raw NM-M | F7: 18 | G7: 45 | H7: =G7*0.1325 -> 5.9625 | I7: =G7-H7-F7 -> 21.0375 | J7: 2025 season catalyst | K7: eBay Auction | L7: =IFERROR(I7/G7,"") -> 0.4675
H8: =G8*0.136+0.4+4.5+0.75 -> 5.65 | I8: =G8-F8-H8 -> -5.65 | L8: =IFERROR(I8/G8,"")
H9: =G9*0.1+0+4.5+0.75 -> 5.25 | I9: =G9-F9-H9 -> -5.25 | L9: =IFERROR(I9/G9,"")
H10: =G10*0.136+0.4+4.5+0.75 -> 5.65 | I10: =G10-F10-H10 -> -5.65 | L10: =IFERROR(I10/G10,"")
H11: =G11*0.136+0.4+4.5+0.75 -> 5.65 | I11: =G11-F11-H11 -> -5.65 | L11: =IFERROR(I11/G11,"")
H12: =G12*0.136+0.4+4.5+0.75 -> 5.65 | I12: =G12-F12-H12 -> -5.65 | L12: =IFERROR(I12/G12,"")
H13: =G13*0.1+0+4.5+0.75 -> 5.25 | I13: =G13-F13-H13 -> -5.25 | L13: =IFERROR(I13/G13,"")
H14: =G14*0.136+0.4+4.5+0.75 -> 5.65 | I14: =G14-F14-H14 -> -5.65 | L14: =IFERROR(I14/G14,"")
H15: =G15*0.136+0.4+4.5+0.75 -> 5.65 | I15: =G15-F15-H15 -> -5.65 | L15: =IFERROR(I15/G15,"")
H16: =G16*0.136+0.4+4.5+0.75 -> 5.65 | I16: =G16-F16-H16 -> -5.65 | L16: =IFERROR(I16/G16,"")
H17: =G17*0.1+0+4.5+0.75 -> 5.25 | I17: =G17-F17-H17 -> -5.25 | L17: =IFERROR(I17/G17,"")
H18: =G18*0.1+0+4.5+0.75 -> 5.25 | I18: =G18-F18-H18 -> -5.25 | L18: =IFERROR(I18/G18,"")
H19: =G19*0.136+0.4+4.5+0.75 -> 5.65 | I19: =G19-F19-H19 -> -5.65 | L19: =IFERROR(I19/G19,"")
H20: =G20*0.1+0+4.5+0.75 -> 5.25 | I20: =G20-F20-H20 -> -5.25 | L20: =IFERROR(I20/G20,"")
H21: =G21*0.1+0+4.5+0.75 -> 5.25 | I21: =G21-F21-H21 -> -5.25 | L21: =IFERROR(I21/G21,"")
H22: =G22*0.1+0+4.5+0.75 -> 5.25 | I22: =G22-F22-H22 -> -5.25 | L22: =IFERROR(I22/G22,"")
H23: =G23*0.068+0.4+4.5+0.75 -> 5.65 | I23: =G23-F23-H23 -> -5.65 | L23: =IFERROR(I23/G23,"")
H24: =G24*0.136+0.4+4.5+0.75 -> 5.65 | I24: =G24-F24-H24 -> -5.65 | L24: =IFERROR(I24/G24,"")
H25: =G25*0.136+0.4+4.5+0.75 -> 5.65 | I25: =G25-F25-H25 -> -5.65 | L25: =IFERROR(I25/G25,"")
H26: =G26*0.068+0.4+4.5+0.75 -> 5.65 | I26: =G26-F26-H26 -> -5.65 | L26: =IFERROR(I26/G26,"")
H27: =G27*0.1+0+4.5+0.75 -> 5.25 | I27: =G27-F27-H27 -> -5.25 | L27: =IFERROR(I27/G27,"")
H28: =G28*0.136+0.4+4.5+0.75 -> 5.65 | I28: =G28-F28-H28 -> -5.65 | L28: =IFERROR(I28/G28,"")
H29: =G29*0.1+0+4.5+0.75 -> 5.25 | I29: =G29-F29-H29 -> -5.25 | L29: =IFERROR(I29/G29,"")
H30: =G30*0.136+0.4+4.5+0.75 -> 5.65 | I30: =G30-F30-H30 -> -5.65 | L30: =IFERROR(I30/G30,"")
H31: =G31*0.136+0.4+4.5+0.75 -> 5.65 | I31: =G31-F31-H31 -> -5.65 | L31: =IFERROR(I31/G31,"")
H32: =G32*0.136+0.4+4.5+0.75 -> 5.65 | I32: =G32-F32-H32 -> -5.65 | L32: =IFERROR(I32/G32,"")
H33: =G33*0.1+0+4.5+0.75 -> 5.25 | I33: =G33-F33-H33 -> -5.25 | L33: =IFERROR(I33/G33,"")
H34: =G34*0.136+0.4+4.5+0.75 -> 5.65 | I34: =G34-F34-H34 -> -5.65 | L34: =IFERROR(I34/G34,"")
H35: =G35*0.136+0.4+4.5+0.75 -> 5.65 | I35: =G35-F35-H35 -> -5.65 | L35: =IFERROR(I35/G35,"")
H36: =G36*0.136+0.4+4.5+0.75 -> 5.65 | I36: =G36-F36-H36 -> -5.65 | L36: =IFERROR(I36/G36,"")
H37: =G37*0.1+0+4.5+0.75 -> 5.25 | I37: =G37-F37-H37 -> -5.25 | L37: =IFERROR(I37/G37,"")
H38: =G38*0.136+0.4+4.5+0.75 -> 5.65 | I38: =G38-F38-H38 -> -5.65 | L38: =IFERROR(I38/G38,"")
H39: =G39*0.1+0+4.5+0.75 -> 5.25 | I39: =G39-F39-H39 -> -5.25 | L39: =IFERROR(I39/G39,"")
H40: =G40*0.136+0.4+4.5+0.75 -> 5.65 | I40: =G40-F40-H40 -> -5.65 | L40: =IFERROR(I40/G40,"")
...

Sheet Inventory Intel
A1: 🏠 Start Here
A2: Based on your 4/20/26 active listings export — 4,233 items, 430 orders last 90d
A4: 1. INVENTORY PRICE COMPOSITION
A5: Price Bucket | B5: # Listings | C5: % of Total | D5: Category
A6: <$2 | B6: 2251 | C6: 0.53177416 | D6: LOW-END (sub-$5)
A7: $2-5 | B7: 1511 | C7: 0.35695724 | D7: LOW-END (sub-$5)
A8: $5-10 | B8: 263 | C8: 0.062130876 | D8: VOLUME TIER
A9: $10-20 | B9: 126 | C9: 0.029766123 | D9: VOLUME TIER
A10: $20-50 | B10: 55 | C10: 0.012993149 | D10: MID-TIER (sweet spot)
A11: $50-100 | B11: 14 | C11: 0.003307347 | D11: MID-TIER (sweet spot)
A12: >=$100 | B12: 13 | C12: 0.003071108 | D12: PREMIUM
A13: ⚠ KEY FINDING: 89% of your listings are under $5. Your mid-tier ($20-100) sweet spot is only 1.6% — this is the #1 reason you're capped at $3-8k/mo NET.
A15: 2. LAST 90 DAYS — SALES PROFILE
A16: Orders (90d) | B16: 430
A17: Total GMV | B17: 7029.83
A18: Avg sale price | B18: 16.348442
A19: Avg orders/day | B19: 4.7777778
A20: Monthly GMV run-rate | B20: 2343.2767
A21: Implied NET @ 30% margin | B21: 702.983
A23: 3. TARGET-LIST PLAYERS WITH SALES (last 90d)
A24: Player | B24: # Sold | C24: Avg $ | D24: Total $
A25: Messi | B25: 2 | C25: 24 | D25: 48
A26: Drake Maye | B26: 5 | C26: 9.034 | D26: 45.17
A27: Bo Nix | B27: 1 | C27: 41 | D27: 41
A28: Lamine Yamal | B28: 2 | C28: 15.995 | D28: 31.99
A29: Haaland | B29: 1 | C29: 9.08 | D29: 9.08
A30: Caleb Williams | B30: 1 | C30: 2.25 | D30: 2.25
A32: 4. YOUR TOP 10 SALES (last 90d) — WHAT'S ACTUALLY MOVING
A33: Sold For | B33: Title
A34: 600 | B34: 2025-26 Topps Chrome Kon Knueppel #254 (RC) Purple RayWave Hornets /75
A35: 425 | B35: Cooper Flagg 2025-26 Topps Chrome RC Silver X-Fractor Refractor #251
A36: 305 | B36: 2025-26 Topps Cooper Flagg #201 Gold Dallas Mavericks #/2025 (RC) 🔥🔥🔥
A37: 222 | B37: 2025-26 Topps Kon Knueppel #NA-KK New Applicants Autographs Hornets (AU), (RC)
A38: 185 | B38: 2025 Topps Update Chrome #98 Paul Skenes Gold Cup Gold Refractor 16/50
A39: 135 | B39: 2024 Topps Aaron Judge #HL-3 Heavy Lumber Yankees MVP
A40: 130 | B40: 2024 Bowman Draft Konnor Griffin #BDC-22 1st Refractor RC Pirates Top Prospect
A41: 122.5 | B41: 1909-11 T206 Sweet Caporal 350/30 Chief Bender #PR Pitching, Trees In Back
A42: 120 | B42: 2024 Bowman Draft Konnor Griffin #BDC-22 Chrome Refractor Pittsburgh Pirates
A43: 117.5 | B43: 2024 Pokemon Japanese Sv8a-Terastal Fest Ex #206 Glaceon Ex Sp Art Rare PSA 10
A45: 5. DATA-DRIVEN RECOMMENDATIONS
...

Sheet Stale Action Plan
A1: 🏠 Start Here
A2: Stale = 0 watchers, 0 bids, listed 30+ days ago. Based on 4,252 active listings.
A4: 1. STALE INVENTORY OVERVIEW
A5: Total active listings | E5: 4252
A6: Stale listings (30+ days, no interest) | E6: 3541
A7: Stale % of inventory | E7: 0.83278457
A8: Capital tied in stale listings | E8: 9758.39
A9: Stale with demand (reprice) | E9: 53
A10: Stale with no demand (consign/bulk) | E10: 3488
A11: Stale premium $20+ 60d+ | E11: 17
A12: Premium stale capital | E12: 508.72
A14: ⚠ 83% of your inventory is stale. $9,758 of working capital is locked up. The 3 plays below free it back into your turn.
A16: 2. STALE AGE BREAKDOWN
A17: Age Bucket | B17: # Stale | C17: Action
A18: 30-60 days | B18: 461 | C18: Reprice to market avg, add keyword tags
A19: 60-90 days | B19: 188 | C19: Audit photos/description, drop 10% or route to consign
A20: 90-180 days | B20: 782 | C20: Consign to DcSports87 or bundle as lots
A21: 180-365 days | B21: 2110 | C21: Bulk lot on Whatnot or consign — stop paying insertion fees
A22: 1+ year | B22: 0 | C22: Delist or bulk lot — zero chance at sticker price
A24: 3. TOP 30 REPRICE CANDIDATES — stale but same card sold in last 90d
A25: 💡 These cards sat with zero interest, BUT identical cards sold recently. Green = list above market (reprice DOWN). Red = list below market (reprice UP). Aim for 95-100% of sold avg.
A26: Days | B26: Your Ask | C26: Sold Avg | D26: Max Sale | E26: Δ% | F26: Qty | G26: Title | H26: New Price Target
A27: 43 | B27: 26 | C27: 5.66 | D27: 11 | E27: 3.5936396 | F27: 1 | G27: 2025 Bowman Draft Ethan Frey #BDC-67 Chrome Purple Refractor Astros #/250 | H27: 5.377
A28: 75 | B28: 13 | C28: 8.18 | D28: 8.18 | E28: 0.58924205 | F28: 1 | G28: 2024 Donruss Optic Drake Maye #229 New England Patriots RC | H28: 7.771
A29: 37 | B29: 13 | C29: 3.5 | D29: 3.5 | E29: 2.7142857 | F29: 1 | G29: 2025-26 Finest Allen Iverson #M-1 Muse Sky Blue Refractor 76ers #/150 | H29: 3.325
A30: 49 | B30: 12 | C30: 8.75 | D30: 11 | E30: 0.37142857 | F30: 1 | G30: 2025 Bowman Draft Eli Willits #BDC-1 Chrome Refractor Washington Nationals | H30: 8.3125
A31: 37 | B31: 10 | C31: 1 | D31: 1 | E31: 9 | F31: 1 | G31: 2025-26 Topps Chrome Noa Essengue #262 Negative Refractor Chicago Bulls | H31: 0.95
A32: 52 | B32: 7.55 | C32: 2.245 | D32: 2.5 | E32: 2.363029 | F32: 1 | G32: 2025 Bowman Draft Ryan Mitchell #BDC-77 Chrome Sky Blue Refractor Cardinals | H32: 2.13275
A33: 152 | B33: 6 | C33: 1.25 | D33: 1.25 | E33: 3.8 | F33: 1 | G33: 2025 Panini Prizm FIFA Club World Cup Ian Subiabre #176 River Plate | H33: 1.1875
A34: 50 | B34: 5.99 | C34: 25.75 | D34: 40 | E34: -0.76737864 | F34: 1 | G34: 2025 Bowman Draft Liam Doyle #BDC-12 Chrome Refractor St. Louis Cardinals | H34: 27.0375
A35: 51 | B35: 5.95 | C35: 3.99 | D35: 3.99 | E35: 0.49122807 | F35: 1 | G35: 2025 Bowman Draft Justin Lamkin #BDC-62 Chrome Sparkle Refractor Royals | H35: 3.7905
A36: 100 | B36: 4.99 | C36: 8.2966667 | D36: 20 | E36: -0.39855364 | F36: 1 | G36: 2025-26 Topps Chrome VJ Edgecombe #253 Philadelphia 76ers | H36: 8.7115
A37: 54 | B37: 1.59 | C37: 1.99 | D37: 1.99 | E37: -0.20100503 | F37: 3 | G37: 2025-26 Topps Chrome Ryan Kalkbrenner #284 Charlotte Hornets | H37: 2.0895
A38: 55 | B38: 3.99 | C38: 5.66 | D38: 11 | E38: -0.295053 | F38: 1 | G38: 2025 Bowman Draft Ethan Frey #BDC-67 Chrome Refractor Houston Astros | H38: 5.943
... A56: 98 | B56: 1.99 | C56: 1.99 | D56: 1.99 | E56: 0 | F56: 1 | G56: 2024 Bowman University Chrome Luther Burden III #55B-1 Tigers | H56: 2.0895
A58: 4. STALE DUPLICATES — bulk lot or consign (3+ copies, no recent sale)
A59: These are accumulating with no demand. Bundle in lots of 25-50 on Whatnot or route to DcSports87 — stop paying insertion fees to re-list monthly.
A60: Count | B60: Ask Each | C60: Total Value | D60: Card
A61: 17 | B61: 2.32 | C61: 40.55 | D61: 2018-19 Topps Match Attax UEFA Champions League Filipe Luís #22 Atletico Madrid | H61: Bundle as lot
A62: 7 | B62: 1.49 | C62: 11.93 | D62: 2024-25 Topps Finest Uefa Club Competitions - Joao Simoes #83 Refractor (RC) | H62: Bundle as lot
...

Sheet 14-Day Volume Ramp
A1: 🏠 Start Here
A2: Tactical day-by-day plan. Volume comes from listing throughput + pricing discipline + Whatnot pushes.
A4: THE MATH — what has to happen
B5: Metric | C5: Current | D5: Week 1 Target | E5: Week 2 Target | F5: End-State
B6: Cards listed / day | C6: 50 | D6: 70 (+helper) | E6: 90-100 | F6: 100
B7: 30-day sell-through rate | C7: 60% | D7: 65% | E7: 68% | F7: 70%
B8: Cards sold / day (implied) | C8: 30 | D8: 40 | E8: 55 | F8: 65+
B9: Pricing discipline (% of median) | C9: 92% | D9: 90% | E9: 88% | F9: 88%
B10: Whatnot auction streams / week | C10: 0 | D10: 1 (50-80 cards) | E10: 2 (100+ cards) | F10: 2-3
B11: eBay 7-day auction listings / wk | C11: 0 | D11: 30 (aged inv.) | E11: 50+ | F11: 50+
A15: DAY-BY-DAY TACTICAL PLAN
B17: Day | C17: Focus | D17: Tactical Actions | E17: List Target | F17: Sold Target | G17: Whatnot? | H17: Price Rule | I17: Notes
B18: 1 (Mon) | C18: Helper onboarding | D18: Hire helper (10 hrs/wk). Write photo SOP. You list 50, helper observes + lists 10 trial. | E18: 60 | F18: 30 | G18: No | H18: 92% median
B19: 2 (Tue) | C19: Helper solo listing | D19: Helper lists 25 (QA every one). You list 50 + 30 Whatnot auction prep. | E19: 75 | F19: 35 | G19: Prep | H19: 92%
B20: 3 (Wed) | C20: Whatnot stream #1 | D20: Helper lists 30. You prep Whatnot (50 cards). 7-10pm live stream — clear aged inventory. | E20: 80 | F20: 45 | G20: YES | H20: Auction
B21: 4 (Thu) | C21: Recovery + list | D21: Helper lists 35. You list 45 + ship from Whatnot stream. | E21: 80 | F21: 40 | G21: No | H21: 92%
B22: 5 (Fri) | C22: eBay 7-day auctions | D22: Helper lists 40. You post 30 eBay auctions of aged 30+ day inventory at $0.99 start. | E22: 70 | F22: 42 | G22: No | H22: Auction
B23: 6 (Sat) | C23: Source day | D23: Helper off. You list 25 AM then hunt FB/eBay lots 3 hrs (use Lot Evaluator). List buys same day. | E23: 50 | F23: 40 | G23: No | H23: 90%
B24: 7 (Sun) | C24: Whatnot stream #2 | D24: You prep 60 cards. 6-9pm Whatnot stream — mix mid-tier + bulk. | E24: 60 | F24: 55 | G24: YES | H24: Auction
B25: 8 (Mon) | C25: Price cuts + re-list | D25: Helper 40. You re-price everything listed 30+ days: drop to 88%. List 40 new. | E25: 80 | F25: 45 | G25: No | H25: 88% on aged
B26: 9 (Tue) | C26: Helper at full speed | D26: Helper lists 50 (SOP dialed). You list 40. Total output: 90/day. | E26: 90 | F26: 50 | G26: No | H26: 88%
B27: 10 (Wed) | C27: Whatnot + aged cleanup | D27: Helper lists 45. You prep Whatnot (80 cards) — push aged + new. 7-10pm stream. | E27: 80 | F27: 60 | G27: YES | H27: Auction
B28: 11 (Thu) | C28: Consignment batch | D28: Helper lists 45. You pack 40 cards to DcSports87 + 30 to Probstein. List 35. | E28: 80 | F28: 50 | G28: No | H28: 88%
B29: 12 (Fri) | C29: eBay auctions + FB lot push | D29: Helper lists 50. You list 35 + post FB Marketplace bulk lot. Daily shipping. | E29: 85 | F29: 50 | G29: No | H29: 88%
... B31: 14 (Sun) | C31: Whatnot stream #3 + review | D31: Prep 100-card stream. 6-10pm. Post-stream: review KPIs, set Week 3 targets. | E31: 100 | F31: 65 | G31: YES | H31: Auction
B32: 14-DAY TOTAL | E32: =SUM(E18:E31) -> 1060 | F32: =SUM(F18:F31) -> 652
A35: THE FIVE LEVERS — ranked by impact
B37: 1. Helper hire (Day 1)
B38: Moves listing capacity from 50 → 90+/day. Single biggest unlock. $600/mo cost for ~$9k revenue add.
B39: 2. Whatnot weekly streams
B40: One 2-3 hour stream moves 50-100 cards. Live price discovery + impulse buying. 3 streams in 14 days = 300+ cards sold.
B41: 3. Pricing discipline
B42: Drop from 92% to 88% of median comp on aged inventory. Accelerates 30-day sell-through by 5-8 pts. Worth more than you think.
B43: 4. eBay 7-day auctions
B44: Auction-format listings with $0.99 start clear aged inventory hard. Run 30-50 aged cards per week as auctions.
B45: 5. Consignment batching
B46: Day 11 send 70 cards out to DcSports87 + Probstein. Frees capital + moves volume while your hands do other things.
A49: REALITY CAVEAT
A50: Hitting 50 sold/day is aggressive from 30/day baseline. Day-by-day targets assume helper hire happens Day 1, Whatnot streams execute on schedule, and pricing discipline is enforced. Realistic completion rate is 80-90% of this plan. If you hit 42-45 sold/day by Day 14, you're still massively ahead of where you started — adjust expectations accordingly.

Sheet Sales Log
A1: 🏠 Start Here
A2: Every direct-sale transaction. Enter new rows at the bottom.
A3: TOTALS → | E3: =SUM(E5:E734) -> 55 | F3: =SUM(F5:F734) -> 128 | G3: =SUM(G5:G734) -> 16.97 | H3: =SUM(H5:H734) -> 9 | I3: =SUM(I5:I734) -> 2.25 | J3: =SUM(J5:J734) -> 44.78 | K3: =IFERROR(J3/F3,"") -> 0.34984375
A4: Sale Date | B4: Channel | C4: Card Description | D4: Category | E4: Cost Basis ($) | F4: Sell Price ($) | G4: Fees ($) | H4: Shipping Cost ($) | I4: Supplies ($) | J4: Net ($) | K4: Margin % | L4: Days Held
A5: 46037 | B5: eBay | C5: 2024 Panini Prizm Patrick Mahomes RC Base #168 | D5: Football | E5: 18 | F5: 42 | G5: 5.57 | H5: 4.5 | I5: 0.75 | J5: =IFERROR(F5-E5-G5-H5-I5,"") -> 13.18 | K5: =IFERROR(J5/F5,"") -> 0.31380952
A6: 46054 | B6: eBay | C6: 2023 Topps Chrome Corbin Carroll RC #150 | D6: Baseball | E6: 12 | F6: 28 | G6: 3.71 | H6: 4.5 | I6: 0.75 | J6: =IFERROR(F6-E6-G6-H6-I6,"") -> 7.04 | K6: =IFERROR(J6/F6,"") -> 0.25142857
A7: 46091 | B7: Whatnot | C7: 2021 Panini Prizm LeBron James #129 Silver | D7: Basketball | E7: 25 | F7: 58 | G7: 7.69 | H7: 0 | I7: 0.75 | J7: =IFERROR(F7-E7-G7-H7-I7,"") -> 24.56 | K7: =IFERROR(J7/F7,"") -> 0.42344828
J8: =IFERROR(F8-E8-G8-H8-I8,"") -> 0 | K8: =IFERROR(J8/F8,"")
J9: =IFERROR(F9-E9-G9-H9-I9,"") -> 0 | K9: =IFERROR(J9/F9,"")
J10: =IFERROR(F10-E10-G10-H10-I10,"") -> 0 | K10: =IFERROR(J10/F10,"")
J11: =IFERROR(F11-E11-G11-H11-I11,"") -> 0 | K11: =IFERROR(J11/F11,"")
J12: =IFERROR(F12-E12-G12-H12-I12,"") -> 0 | K12: =IFERROR(J12/F12,"")
J13: =IFERROR(F13-E13-G13-H13-I13,"") -> 0 | K13: =IFERROR(J13/F13,"")
J14: =IFERROR(F14-E14-G14-H14-I14,"") -> 0 | K14: =IFERROR(J14/F14,"")
J15: =IFERROR(F15-E15-G15-H15-I15,"") -> 0 | K15: =IFERROR(J15/F15,"")
J16: =IFERROR(F16-E16-G16-H16-I16,"") -> 0 | K16: =IFERROR(J16/F16,"")
J17: =IFERROR(F17-E17-G17-H17-I17,"") -> 0 | K17: =IFERROR(J17/F17,"")
J18: =IFERROR(F18-E18-G18-H18-I18,"") -> 0 | K18: =IFERROR(J18/F18,"")
J19: =IFERROR(F19-E19-G19-H19-I19,"") -> 0 | K19: =IFERROR(J19/F19,"")
... J714: =IFERROR(F714-E714-G714-H714-I714,"") -> 0 | K714: =IFERROR(J714/F714,"")

Sheet Consignment Tracker
A1: 🏠 Start Here
A2: DcSports87, Probstein, PWCC, MyBrick submissions and net payouts.
A3: TOTALS → | C3: =SUM(C5:C104) -> 0 | G3: =SUM(G5:G104) -> 0 | H3: =SUM(H5:H104) -> 0 | I3: =SUM(I5:I104) -> 0 | J3: =IFERROR(I3/C3,"")
A4: Submission Date | B4: House | C4: # Cards | D4: Your Est. Value ($) | E4: Card Type Focus | F4: Auction Close Date | G4: Gross Proceeds ($) | H4: House Fees ($) | I4: Net Received ($) | J4: Net / Card ($)
I5: =IFERROR(G5-H5,"") -> 0 | J5: =IFERROR(I5/C5,"")
I6: =IFERROR(G6-H6,"") -> 0 | J6: =IFERROR(I6/C6,"")
I7: =IFERROR(G7-H7,"") -> 0 | J7: =IFERROR(I7/C7,"")
I8: =IFERROR(G8-H8,"") -> 0 | J8: =IFERROR(I8/C8,"")
I9: =IFERROR(G9-H9,"") -> 0 | J9: =IFERROR(I9/C9,"")
I10: =IFERROR(G10-H10,"") -> 0 | J10: =IFERROR(I10/C10,"")
I11: =IFERROR(G11-H11,"") -> 0 | J11: =IFERROR(I11/C11,"")
I12: =IFERROR(G12-H12,"") -> 0 | J12: =IFERROR(I12/C12,"")
I13: =IFERROR(G13-H13,"") -> 0 | J13: =IFERROR(I13/C13,"")
I14: =IFERROR(G14-H14,"") -> 0 | J14: =IFERROR(I14/C14,"")
I15: =IFERROR(G15-H15,"") -> 0 | J15: =IFERROR(I15/C15,"")
I16: =IFERROR(G16-H16,"") -> 0 | J16: =IFERROR(I16/C16,"")
... I104: =IFERROR(G104-H104,"") -> 0 | J104: =IFERROR(I104/C104,"")
B110: =COUNTIF(B5:B104,A110) -> 0 | C110: =SUMIF(B5:B104,A110,C5:C104) -> 0 | D110: =SUMIF(B5:B104,A110,I5:I104) -> 0 | E110: =IFERROR(D110/C110,"")
B111: =COUNTIF(B5:B104,A111) -> 0 | C111: =SUMIF(B5:B104,A111,C5:C104) -> 0 | D111: =SUMIF(B5:B104,A111,I5:I104) -> 0 | E111: =IFERROR(D111/C111,"")
B112: =COUNTIF(B5:B104,A112) -> 0 | C112: =SUMIF(B5:B104,A112,C5:C104) -> 0 | D112: =SUMIF(B5:B104,A112,I5:I104) -> 0 | E112: =IFERROR(D112/C112,"")
B113: =COUNTIF(B5:B104,A113) -> 0 | C113: =SUMIF(B5:B104,A113,C5:C104) -> 0 | D113: =SUMIF(B5:B104,A113,I5:I104) -> 0 | E113: =IFERROR(D113/C113,"")
B114: =COUNTIF(B5:B104,A114) -> 0 | C114: =SUMIF(B5:B104,A114,C5:C104) -> 0 | D114: =SUMIF(B5:B104,A114,I5:I104) -> 0 | E114: =IFERROR(D114/C114,"")

Sheet DcSports87 May 2026
A1: 🏠 Start Here
A2: Generated: May 03, 2026 | Top 20 by score, all listed > $25 | Est. Total Value: $2,040.17
A4: # | B4: Card Description | C4: Category | D4: Listed Price ($) | E4: Score | F4: Watchers | G4: Market Verdict | H4: DcSports87 Notes
D26: =SUM(D5:D24) -> 0

Sheet DcSports87 — Normal Batch
A1: 🏠 Start Here
A2: 75 cards | $3–$25 range | Total listed value: $829.38 | Avg: $11.06/card | All modern (no vintage) | Sorted by auction potential score (highest first)
A3: SCORE = Auto +8 | RC/1st +3 | Chrome/Prizm +2 | Print run (/25=+6, /99=+4, /199=+3, /499=+2, higher=+1) | Patch/Swatch +3 | Jersey/Relic +2 | Price tier ($3-8=+1, $8-15=+2, $15-25=+3) | Watchers = +N each
A5: # | B5: Card Description | C5: Category | D5: Listed ($) | E5: Score | F5: Score Breakdown | G5: Watchers | H5: SKU
D82: =SUM(D6:D80) -> 0 | E82: =AVERAGE(E6:E80) -> #DIV/0!

Sheet Inventory & Aging
A1: 🏠 Start Here
B2: Track every card you own: when you bought it, when you listed it, and how long it's been sitting. Aging is based on Listed Date — the 60-day clock starts when it goes live.
A3: SUMMARY → | B3: Active listings: | C3: =COUNTIF(H5:H504,"Listed") -> 0 | D3: Stale (≥60d): | E3: =COUNTIF(J5:J504,"STALE — route now") -> 0 | F3: Capital at risk ($): | G3: =SUMIFS(F5:F504,J5:J504,"STALE — route now") -> 0 | H3: Avg days listed: | I3: =IFERROR(AVERAGEIF(H5:H504,"Listed",I5:I504),"—") -> —
A4: Acquired | B4: Listed Date | C4: Source | D4: Card Description | E4: Category | F4: Cost Basis ($) | G4: Listed Price ($) | H4: Status | I4: Days Listed | J4: Aging Flag | K4: Next Action
I9: =IF(OR(B9="",H9="Sold"),"—",TODAY()-B9) -> — | J9: =IF(OR(B9="",H9="Sold"),"",IF(I9="—","",IF(I9>=60,"STALE — route now",IF(I9>=30,"Aging — watch",IF(I9>=0,"Fresh",""))))) | K9: =IF(J9="STALE — route now","→ Send to consignment batch",IF(J9="Aging — watch","→ Consider 10% price drop",IF(J9="Fresh","→ Hold & monitor","")))
I11: =IF(OR(B11="",H11="Sold"),"—",TODAY()-B11) -> — | J11: =IF(OR(B11="",H11="Sold"),"",IF(I11="—","",IF(I11>=60,"STALE — route now",IF(I11>=30,"Aging — watch",IF(I11>=0,"Fresh",""))))) | K11: =IF(J11="STALE — route now","→ Send to consignment batch",IF(J11="Aging — watch","→ Consider 10% price drop",IF(J11="Fresh","→ Hold & monitor","")))
I12: =IF(OR(B12="",H12="Sold"),"—",TODAY()-B12) -> — | J12: =IF(OR(B12="",H12="Sold"),"",IF(I12="—","",IF(I12>=60,"STALE — route now",IF(I12>=30,"Aging — watch",IF(I12>=0,"Fresh",""))))) | K12: =IF(J12="STALE — route now","→ Send to consignment batch",IF(J12="Aging — watch","→ Consider 10% price drop",IF(J12="Fresh","→ Hold & monitor","")))
I13: =IF(OR(B13="",H13="Sold"),"—",TODAY()-B13) -> — | J13: =IF(OR(B13="",H13="Sold"),"",IF(I13="—","",IF(I13>=60,"STALE — route now",IF(I13>=30,"Aging — watch",IF(I13>=0,"Fresh",""))))) | K13: =IF(J13="STALE — route now","→ Send to consignment batch",IF(J13="Aging — watch","→ Consider 10% price drop",IF(J13="Fresh","→ Hold & monitor","")))
I14: =IF(OR(B14="",H14="Sold"),"—",TODAY()-B14) -> — | J14: =IF(OR(B14="",H14="Sold"),"",IF(I14="—","",IF(I14>=60,"STALE — route now",IF(I14>=30,"Aging — watch",IF(I14>=0,"Fresh",""))))) | K14: =IF(J14="STALE — route now","→ Send to consignment batch",IF(J14="Aging — watch","→ Consider 10% price drop",IF(J14="Fresh","→ Hold & monitor","")))
I15: =IF(OR(B15="",H15="Sold"),"—",TODAY()-B15) -> — | J15: =IF(OR(B15="",H15="Sold"),"",IF(I15="—","",IF(I15>=60,"STALE — route now",IF(I15>=30,"Aging — watch",IF(I15>=0,"Fresh",""))))) | K15: =IF(J15="STALE — route now","→ Send to consignment batch",IF(J15="Aging — watch","→ Consider 10% price drop",IF(J15="Fresh","→ Hold & monitor","")))
I16: =IF(OR(B16="",H16="Sold"),"—",TODAY()-B16) -> — | J16: =IF(OR(B16="",H16="Sold"),"",IF(I16="—","",IF(I16>=60,"STALE — route now",IF(I16>=30,"Aging — watch",IF(I16>=0,"Fresh",""))))) | K16: =IF(J16="STALE — route now","→ Send to consignment batch",IF(J16="Aging — watch","→ Consider 10% price drop",IF(J16="Fresh","→ Hold & monitor","")))
I17: =IF(OR(B17="",H17="Sold"),"—",TODAY()-B17) -> — | J17: =IF(OR(B17="",H17="Sold"),"",IF(I17="—","",IF(I17>=60,"STALE — route now",IF(I17>=30,"Aging — watch",IF(I17>=0,"Fresh",""))))) | K17: =IF(J17="STALE — route now","→ Send to consignment batch",IF(J17="Aging — watch","→ Consider 10% price drop",IF(J17="Fresh","→ Hold & monitor","")))
I18: =IF(OR(B18="",H18="Sold"),"—",TODAY()-B18) -> — | J18: =IF(OR(B18="",H18="Sold"),"",IF(I18="—","",IF(I18>=60,"STALE — route now",IF(I18>=30,"Aging — watch",IF(I18>=0,"Fresh",""))))) | K18: =IF(J18="STALE — route now","→ Send to consignment batch",IF(J18="Aging — watch","→ Consider 10% price drop",IF(J18="Fresh","→ Hold & monitor","")))
I19: =IF(OR(B19="",H19="Sold"),"—",TODAY()-B19) -> — | J19: =IF(OR(B19="",H19="Sold"),"",IF(I19="—","",IF(I19>=60,"STALE — route now",IF(I19>=30,"Aging — watch",IF(I19>=0,"Fresh",""))))) | K19: =IF(J19="STALE — route now","→ Send to consignment batch",IF(J19="Aging — watch","→ Consider 10% price drop",IF(J19="Fresh","→ Hold & monitor","")))
I20: =IF(OR(B20="",H20="Sold"),"—",TODAY()-B20) -> — | J20: =IF(OR(B20="",H20="Sold"),"",IF(I20="—","",IF(I20>=60,"STALE — route now",IF(I20>=30,"Aging — watch",IF(I20>=0,"Fresh",""))))) | K20: =IF(J20="STALE — route now","→ Send to consignment batch",IF(J20="Aging — watch","→ Consider 10% price drop",IF(J20="Fresh","→ Hold & monitor","")))
I21: =IF(OR(B21="",H21="Sold"),"—",TODAY()-B21) -> — | J21: =IF(OR(B21="",H21="Sold"),"",IF(I21="—","",IF(I21>=60,"STALE — route now",IF(I21>=30,"Aging — watch",IF(I21>=0,"Fresh",""))))) | K21: =IF(J21="STALE — route now","→ Send to consignment batch",IF(J21="Aging — watch","→ Consider 10% price drop",IF(J21="Fresh","→ Hold & monitor","")))
... I504: =IF(OR(B504="",H504="Sold"),"—",TODAY()-B504) -> — | J504: =IF(OR(B504="",H504="Sold"),"",IF(I504="—","",IF(I504>=60,"STALE — route now",IF(I504>=30,"Aging — watch",IF(I504>=0,"Fresh",""))))) | K504: =IF(J504="STALE — route now","→ Send to consignment batch",IF(J504="Aging — watch","→ Consider 10% price drop",IF(J504="Fresh","→ Hold & monitor","")))

Sheet Reprice Queue
A1: 🏠 Start Here
A2: Reprice Queue — which listings to price-check today. Paste your eBay active-listings export into the grey columns (A–E). The queue flags itself by tier. Tiers 2 & 3 qualify instantly from the export; Tier 1 needs the app's CardHedger velocity pull.
A3: SUMMARY → | B3: Total listings: | C3: =COUNTA($B$5:$B$4600) -> 4480 | D3: In queue: | E3: =COUNTIF($H$5:$H$4600,"TIER*") -> 16 | F3: Needs API check: | G3: =COUNTIF($J$5:$J$4600,"YES*") -> 64 | H3: ="T1 "&COUNTIF($H$5:$H$4600,"TIER 1")&" | T2 "&COUNTIF($H$5:$H$4600,"TIER 2")&" | T3 "&COUNTIF($H$5:$H$4600,"TIER 3") -> T1 0 | T2 14 | T3 2
A4: Item # | B4: Title | C4: SKU / Custom Label | D4: Current Price ($) | E4: Daily Sales (mkt/day) | F4: Graded? | G4: PSA Grade | H4: QUALIFIES (Tier) | I4: Reason / Action | J4: Needs velocity pull?
A5: 226788716936 | B5: 2025 Bowman - Bowman Scouts Top 100 Marcelo Mayer #BTP-4 (RC) | C5: CDP-388FFD0 | D5: 1.49 | F5: =IF($B5="","",IF(ISNUMBER(SEARCH("PSA",$B5)),"Yes","No")) -> No | G5: =IF($B5="","",IF(ISNUMBER(SEARCH("PSA 10",$B5)),10,IF(ISNUMBER(SEARCH("PSA 9.5",$B5)),9.5,IF(ISNUMBER(SEARCH("PSA 9",$B5)),9,IF(ISNUMBER(SEARCH("PSA 8",$B5)),8,IF(ISNUMBER(SEARCH("PSA",$B5)),"<9","")))))) | H5: =IF($B5="","",IF($D5>=100,"TIER 2",IF(OR(ISNUMBER(SEARCH("PSA 10",$B5)),ISNUMBER(SEARCH("PSA 9.5",$B5)),ISNUMBER(SEARCH("PSA 9",$B5))),"TIER 3",IF(AND($D5>20,N($E5)>=15),"TIER 1","—")))) -> — | I5: =IF($B5="","",IF($D5>=100,"Premium $100+ (auto)",IF(OR(ISNUMBER(SEARCH("PSA 10",$B5)),ISNUMBER(SEARCH("PSA 9.5",$B5)),ISNUMBER(SEARCH("PSA 9",$B5))),"Graded PSA 9+ (auto)",IF(AND($D5>20,N($E5)>=15),"Hot: $20+ & "&$E5&"/day",IF($D5>20,"$20+ — needs velocity check","Below thresholds"))))) -> Below thresholds | J5: =IF($B5="","",IF(AND($D5>20,$D5<100,NOT(OR(ISNUMBER(SEARCH("PSA 10",$B5)),ISNUMBER(SEARCH("PSA 9.5",$B5)),ISNUMBER(SEARCH("PSA 9",$B5)))),$E5=""),"YES — pull CardHedger",""))
A6: 226788720400 | B6: 2024 Panini Absolute - Star Gazing Luke McCaffrey #SG-LMY (RC) | C6: CDP-B6E7E18 | D6: 0.99 | F6: =IF($B6="","",IF(ISNUMBER(SEARCH("PSA",$B6)),"Yes","No")) -> No | G6: =IF($B6="","",IF(ISNUMBER(SEARCH("PSA 10",$B6)),10,IF(ISNUMBER(SEARCH("PSA 9.5",$B6)),9.5,IF(ISNUMBER(SEARCH("PSA 9",$B6)),9,IF(ISNUMBER(SEARCH("PSA 8",$B6)),8,IF(ISNUMBER(SEARCH("PSA",$B6)),"<9","")))))) | H6: =IF($B6="","",IF($D6>=100,"TIER 2",IF(OR(ISNUMBER(SEARCH("PSA 10",$B6)),ISNUMBER(SEARCH("PSA 9.5",$B6)),ISNUMBER(SEARCH("PSA 9",$B6))),"TIER 3",IF(AND($D6>20,N($E6)>=15),"TIER 1","—")))) -> — | I6: =IF($B6="","",IF($D6>=100,"Premium $100+ (auto)",IF(OR(ISNUMBER(SEARCH("PSA 10",$B6)),ISNUMBER(SEARCH("PSA 9.5",$B6)),ISNUMBER(SEARCH("PSA 9",$B6))),"Graded PSA 9+ (auto)",IF(AND($D6>20,N($E6)>=15),"Hot: $20+ & "&$E6&"/day",IF($D6>20,"$20+ — needs velocity check","Below thresholds"))))) -> Below thresholds | J6: =IF($B6="","",IF(AND($D6>20,$D6<100,NOT(OR(ISNUMBER(SEARCH("PSA 10",$B6)),ISNUMBER(SEARCH("PSA 9.5",$B6)),ISNUMBER(SEARCH("PSA 9",$B6)))),$E6=""),"YES — pull CardHedger",""))
A7: 226788721897 | B7: 2024 Panini Illusions J.J. McCarthy #100 (RC) Vikings | C7: CDP-5D82D06 | D7: 1.49 | F7: =IF($B7="","",IF(ISNUMBER(SEARCH("PSA",$B7)),"Yes","No")) -> No | G7: =IF($B7="","",IF(ISNUMBER(SEARCH("PSA 10",$B7)),10,IF(ISNUMBER(SEARCH("PSA 9.5",$B7)),9.5,IF(ISNUMBER(SEARCH("PSA 9",$B7)),9,IF(ISNUMBER(SEARCH("PSA 8",$B7)),8,IF(ISNUMBER(SEARCH("PSA",$B7)),"<9","")))))) | H7: =IF($B7="","",IF($D7>=100,"TIER 2",IF(OR(ISNUMBER(SEARCH("PSA 10",$B7)),ISNUMBER(SEARCH("PSA 9.5",$B7)),ISNUMBER(SEARCH("PSA 9",$B7))),"TIER 3",IF(AND($D7>20,N($E7)>=15),"TIER 1","—")))) -> — | I7: =IF($B7="","",IF($D7>=100,"Premium $100+ (auto)",IF(OR(ISNUMBER(SEARCH("PSA 10",$B7)),ISNUMBER(SEARCH("PSA 9.5",$B7)),ISNUMBER(SEARCH("PSA 9",$B7))),"Graded PSA 9+ (auto)",IF(AND($D7>20,N($E7)>=15),"Hot: $20+ & "&$E7&"/day",IF($D7>20,"$20+ — needs velocity check","Below thresholds"))))) -> Below thresholds | J7: =IF($B7="","",IF(AND($D7>20,$D7<100,NOT(OR(ISNUMBER(SEARCH("PSA 10",$B7)),ISNUMBER(SEARCH("PSA 9.5",$B7)),ISNUMBER(SEARCH("PSA 9",$B7)))),$E7=""),"YES — pull CardHedger",""))
A8: 226788723318 | B8: 2025 Bowman Chrome Rece Hinds #RR-8 (RC) Rockstar Rookies | C8: CDP-B676C2C | D8: 1.5 | F8: =IF($B8="","",IF(ISNUMBER(SEARCH("PSA",$B8)),"Yes","No")) -> No | G8: =IF($B8="","",IF(ISNUMBER(SEARCH("PSA 10",$B8)),10,IF(ISNUMBER(SEARCH("PSA 9.5",$B8)),9.5,IF(ISNUMBER(SEARCH("PSA 9",$B8)),9,IF(ISNUMBER(SEARCH("PSA 8",$B8)),8,IF(ISNUMBER(SEARCH("PSA",$B8)),"<9","")))))) | H8: =IF($B8="","",IF($D8>=100,"TIER 2",IF(OR(ISNUMBER(SEARCH("PSA 10",$B8)),ISNUMBER(SEARCH("PSA 9.5",$B8)),ISNUMBER(SEARCH("PSA 9",$B8))),"TIER 3",IF(AND($D8>20,N($E8)>=15),"TIER 1","—")))) -> — | I8: =IF($B8="","",IF($D8>=100,"Premium $100+ (auto)",IF(OR(ISNUMBER(SEARCH("PSA 10",$B8)),ISNUMBER(SEARCH("PSA 9.5",$B8)),ISNUMBER(SEARCH("PSA 9",$B8))),"Graded PSA 9+ (auto)",IF(AND($D8>20,N($E8)>=15),"Hot: $20+ & "&$E8&"/day",IF($D8>20,"$20+ — needs velocity check","Below thresholds"))))) -> Below thresholds | J8: =IF($B8="","",IF(AND($D8>20,$D8<100,NOT(OR(ISNUMBER(SEARCH("PSA 10",$B8)),ISNUMBER(SEARCH("PSA 9.5",$B8)),ISNUMBER(SEARCH("PSA 9",$B8)))),$E8=""),"YES — pull CardHedger",""))
A9: 226788724174 | B9: 2025 Bowman 1st Chrome Jhonayker Ugarte #BCP-123 (RC) Royals | C9: CDP-E37E4FD | D9: 1.99 | F9: =IF($B9="","",IF(ISNUMBER(SEARCH("PSA",$B9)),"Yes","No")) -> No | G9: =IF($B9="","",IF(ISNUMBER(SEARCH("PSA 10",$B9)),10,IF(ISNUMBER(SEARCH("PSA 9.5",$B9)),9.5,IF(ISNUMBER(SEARCH("PSA 9",$B9)),9,IF(ISNUMBER(SEARCH("PSA 8",$B9)),8,IF(ISNUMBER(SEARCH("PSA",$B9)),"<9","")))))) | H9: =IF($B9="","",IF($D9>=100,"TIER 2",IF(OR(ISNUMBER(SEARCH("PSA 10",$B9)),ISNUMBER(SEARCH("PSA 9.5",$B9)),ISNUMBER(SEARCH("PSA 9",$B9))),"TIER 3",IF(AND($D9>20,N($E9)>=15),"TIER 1","—")))) -> — | I9: =IF($B9="","",IF($D9>=100,"Premium $100+ (auto)",IF(OR(ISNUMBER(SEARCH("PSA 10",$B9)),ISNUMBER(SEARCH("PSA 9.5",$B9)),ISNUMBER(SEARCH("PSA 9",$B9))),"Graded PSA 9+ (auto)",IF(AND($D9>20,N($E9)>=15),"Hot: $20+ & "&$E9&"/day",IF($D9>20,"$20+ — needs velocity check","Below thresholds"))))) -> Below thresholds | J9: =IF($B9="","",IF(AND($D9>20,$D9<100,NOT(OR(ISNUMBER(SEARCH("PSA 10",$B9)),ISNUMBER(SEARCH("PSA 9.5",$B9)),ISNUMBER(SEARCH("PSA 9",$B9)))),$E9=""),"YES — pull CardHedger",""))
A10: 226788730875 | B10: 2025 Bowman Chrome Kumar Rocker ROY-5 Texas Rangers | C10: CDP-067FF8D | D10: 1.25 | F10: =IF($B10="","",IF(ISNUMBER(SEARCH("PSA",$B10)),"Yes","No")) -> No | G10: =IF($B10="","",IF(ISNUMBER(SEARCH("PSA 10",$B10)),10,IF(ISNUMBER(SEARCH("PSA 9.5",$B10)),9.5,IF(ISNUMBER(SEARCH("PSA 9",$B10)),9,IF(ISNUMBER(SEARCH("PSA 8",$B10)),8,IF(ISNUMBER(SEARCH("PSA",$B10)),"<9","")))))) | H10: =IF($B10="","",IF($D10>=100,"TIER 2",IF(OR(ISNUMBER(SEARCH("PSA 10",$B10)),ISNUMBER(SEARCH("PSA 9.5",$B10)),ISNUMBER(SEARCH("PSA 9",$B10))),"TIER 3",IF(AND($D10>20,N($E10)>=15),"TIER 1","—")))) -> — | I10: =IF($B10="","",IF($D10>=100,"Premium $100+ (auto)",IF(OR(ISNUMBER(SEARCH("PSA 10",$B10)),ISNUMBER(SEARCH("PSA 9.5",$B10)),ISNUMBER(SEARCH("PSA 9",$B10))),"Graded PSA 9+ (auto)",IF(AND($D10>20,N($E10)>=15),"Hot: $20+ & "&$E10&"/day",IF($D10>20,"$20+ — needs velocity check","Below thresholds"))))) -> Below thresholds | J10: =IF($B10="","",IF(AND($D10>20,$D10<100,NOT(OR(ISNUMBER(SEARCH("PSA 10",$B10)),ISNUMBER(SEARCH("PSA 9.5",$B10)),ISNUMBER(SEARCH("PSA 9",$B10)))),$E10=""),"YES — pull CardHedger",""))
A11: 226788735090 | B11: 2024 Panini Illusions Michael Penix Jr. #4 (RC) Falcons | C11: CDP-6ABA4C8 | D11: 1.25 | F11: =IF($B11="","",IF(ISNUMBER(SEARCH("PSA",$B11)),"Yes","No")) -> No | G11: =IF($B11="","",IF(ISNUMBER(SEARCH("PSA 10",$B11)),10,IF(ISNUMBER(SEARCH("PSA 9.5",$B11)),9.5,IF(ISNUMBER(SEARCH("PSA 9",$B11)),9,IF(ISNUMBER(SEARCH("PSA 8",$B11)),8,IF(ISNUMBER(SEARCH("PSA",$B11)),"<9","")))))) | H11: =IF($B11="","",IF($D11>=100,"TIER 2",IF(OR(ISNUMBER(SEARCH("PSA 10",$B11)),ISNUMBER(SEARCH("PSA 9.5",$B11)),ISNUMBER(SEARCH("PSA 9",$B11))),"TIER 3",IF(AND($D11>20,N($E11)>=15),"TIER 1","—")))) -> — | I11: =IF($B11="","",IF($D11>=100,"Premium $100+ (auto)",IF(OR(ISNUMBER(SEARCH("PSA 10",$B11)),ISNUMBER(SEARCH("PSA 9.5",$B11)),ISNUMBER(SEARCH("PSA 9",$B11))),"Graded PSA 9+ (auto)",IF(AND($D11>20,N($E11)>=15),"Hot: $20+ & "&$E11&"/day",IF($D11>20,"$20+ — needs velocity check","Below thresholds"))))) -> Below thresholds | J11: =IF($B11="","",IF(AND($D11>20,$D11<100,NOT(OR(ISNUMBER(SEARCH("PSA 10",$B11)),ISNUMBER(SEARCH("PSA 9.5",$B11)),ISNUMBER(SEARCH("PSA 9",$B11)))),$E11=""),"YES — pull CardHedger",""))
A12: 226790522118 | B12: 2025 Topps Heritage Baseball #92 Bobby Witt Jr. 👑Kansas City Royals👑 | C12: CDP-E74F701 | D12: 1.99 | F12: =IF($B12="","",IF(ISNUMBER(SEARCH("PSA",$B12)),"Yes","No")) -> No | G12: =IF($B12="","",IF(ISNUMBER(SEARCH("PSA 10",$B12)),10,IF(ISNUMBER(SEARCH("PSA 9.5",$B12)),9.5,IF(ISNUMBER(SEARCH("PSA 9",$B12)),9,IF(ISNUMBER(SEARCH("PSA 8",$B12)),8,IF(ISNUMBER(SEARCH("PSA",$B12)),"<9","")))))) | H12: =IF($B12="","",IF($D12>=100,"TIER 2",IF(OR(ISNUMBER(SEARCH("PSA 10",$B12)),ISNUMBER(SEARCH("PSA 9.5",$B12)),ISNUMBER(SEARCH("PSA 9",$B12))),"TIER 3",IF(AND($D12>20,N($E12)>=15),"TIER 1","—")))) -> — | I12: =IF($B12="","",IF($D12>=100,"Premium $100+ (auto)",IF(OR(ISNUMBER(SEARCH("PSA 10",$B12)),ISNUMBER(SEARCH("PSA 9.5",$B12)),ISNUMBER(SEARCH("PSA 9",$B12))),"Graded PSA 9+ (auto)",IF(AND($D12>20,N($E12)>=15),"Hot: $20+ & "&$E12&"/day",IF($D12>20,"$20+ — needs velocity check","Below thresholds"))))) -> Below thresholds | J12: =IF($B12="","",IF(AND($D12>20,$D12<100,NOT(OR(ISNUMBER(SEARCH("PSA 10",$B12)),ISNUMBER(SEARCH("PSA 9.5",$B12)),ISNUMBER(SEARCH("PSA 9",$B12)))),$E12=""),"YES — pull CardHedger",""))
A13: 226792471627 | B13: 2025 Bowman Connor Norby #46 (RC) Marlins | C13: CDP-4895D6C | D13: 1.5 | F13: =IF($B13="","",IF(ISNUMBER(SEARCH("PSA",$B13)),"Yes","No")) -> No | G13: =IF($B13="","",IF(ISNUMBER(SEARCH("PSA 10",$B13)),10,IF(ISNUMBER(SEARCH("PSA 9.5",$B13)),9.5,IF(ISNUMBER(SEARCH("PSA 9",$B13)),9,IF(ISNUMBER(SEARCH("PSA 8",$B13)),8,IF(ISNUMBER(SEARCH("PSA",$B13)),"<9","")))))) | H13: =IF($B13="","",IF($D13>=100,"TIER 2",IF(OR(ISNUMBER(SEARCH("PSA 10",$B13)),ISNUMBER(SEARCH("PSA 9.5",$B13)),ISNUMBER(SEARCH("PSA 9",$B13))),"TIER 3",IF(AND($D13>20,N($E13)>=15),"TIER 1","—")))) -> — | I13: =IF($B13="","",IF($D13>=100,"Premium $100+ (auto)",IF(OR(ISNUMBER(SEARCH("PSA 10",$B13)),ISNUMBER(SEARCH("PSA 9.5",$B13)),ISNUMBER(SEARCH("PSA 9",$B13))),"Graded PSA 9+ (auto)",IF(AND($D13>20,N($E13)>=15),"Hot: $20+ & "&$E13&"/day",IF($D13>20,"$20+ — needs velocity check","Below thresholds"))))) -> Below thresholds | J13: =IF($B13="","",IF(AND($D13>20,$D13<100,NOT(OR(ISNUMBER(SEARCH("PSA 10",$B13)),ISNUMBER(SEARCH("PSA 9.5",$B13)),ISNUMBER(SEARCH("PSA 9",$B13)))),$E13=""),"YES — pull CardHedger",""))
A14: 226792475559 | B14: 2025 Topps Series 1 Ronald Acuña Jr. #TG-16 Training Grounds Braves | C14: CDP-B954CB1 | D14: 1.49 | F14: =IF($B14="","",IF(ISNUMBER(SEARCH("PSA",$B14)),"Yes","No")) -> No | G14: =IF($B14="","",IF(ISNUMBER(SEARCH("PSA 10",$B14)),10,IF(ISNUMBER(SEARCH("PSA 9.5",$B14)),9.5,IF(ISNUMBER(SEARCH("PSA 9",$B14)),9,IF(ISNUMBER(SEARCH("PSA 8",$B14)),8,IF(ISNUMBER(SEARCH("PSA",$B14)),"<9","")))))) | H14: =IF($B14="","",IF($D14>=100,"TIER 2",IF(OR(ISNUMBER(SEARCH("PSA 10",$B14)),ISNUMBER(SEARCH("PSA 9.5",$B14)),ISNUMBER(SEARCH("PSA 9",$B14))),"TIER 3",IF(AND($D14>20,N($E14)>=15),"TIER 1","—")))) -> — | I14: =IF($B14="","",IF($D14>=100,"Premium $100+ (auto)",IF(OR(ISNUMBER(SEARCH("PSA 10",$B14)),ISNUMBER(SEARCH("PSA 9.5",$B14)),ISNUMBER(SEARCH("PSA 9",$B14))),"Graded PSA 9+ (auto)",IF(AND($D14>20,N($E14)>=15),"Hot: $20+ & "&$E14&"/day",IF($D14>20,"$20+ — needs velocity check","Below thresholds"))))) -> Below thresholds | J14: =IF($B14="","",IF(AND($D14>20,$D14<100,NOT(OR(ISNUMBER(SEARCH("PSA 10",$B14)),ISNUMBER(SEARCH("PSA 9.5",$B14)),ISNUMBER(SEARCH("PSA 9",$B14)))),$E14=""),"YES — pull CardHedger",""))
A15: 226792488707 | B15: 2025 Topps 2024's Greatest Hits #GH-27 Wyatt Langford Texas Rangers | C15: CDP-4C8AF73 | D15: 1.99 | F15: =IF($B15="","",IF(ISNUMBER(SEARCH("PSA",$B15)),"Yes","No")) -> No | G15: =IF($B15="","",IF(ISNUMBER(SEARCH("PSA 10",$B15)),10,IF(ISNUMBER(SEARCH("PSA 9.5",$B15)),9.5,IF(ISNUMBER(SEARCH("PSA 9",$B15)),9,IF(ISNUMBER(SEARCH("PSA 8",$B15)),8,IF(ISNUMBER(SEARCH("PSA",$B15)),"<9","")))))) | H15: =IF($B15="","",IF($D15>=100,"TIER 2",IF(OR(ISNUMBER(SEARCH("PSA 10",$B15)),ISNUMBER(SEARCH("PSA 9.5",$B15)),ISNUMBER(SEARCH("PSA 9",$B15))),"TIER 3",IF(AND($D15>20,N($E15)>=15),"TIER 1","—")))) -> — | I15: =IF($B15="","",IF($D15>=100,"Premium $100+ (auto)",IF(OR(ISNUMBER(SEARCH("PSA 10",$B15)),ISNUMBER(SEARCH("PSA 9.5",$B15)),ISNUMBER(SEARCH("PSA 9",$B15))),"Graded PSA 9+ (auto)",IF(AND($D15>20,N($E15)>=15),"Hot: $20+ & "&$E15&"/day",IF($D15>20,"$20+ — needs velocity check","Below thresholds"))))) -> Below thresholds | J15: =IF($B15="","",IF(AND($D15>20,$D15<100,NOT(OR(ISNUMBER(SEARCH("PSA 10",$B15)),ISNUMBER(SEARCH("PSA 9.5",$B15)),ISNUMBER(SEARCH("PSA 9",$B15)))),$E15=""),"YES — pull CardHedger",""))
A16: 226792491039 | B16: 2025 Topps Series 1 Mookie Betts 1990 Topps Baseball #T90-60 Dodgers | C16: CDP-2EE740C | D16: 1.25 | F16: =IF($B16="","",IF(ISNUMBER(SEARCH("PSA",$B16)),"Yes","No")) -> No | G16: =IF($B16="","",IF(ISNUMBER(SEARCH("PSA 10",$B16)),10,IF(ISNUMBER(SEARCH("PSA 9.5",$B16)),9.5,IF(ISNUMBER(SEARCH("PSA 9",$B16)),9,IF(ISNUMBER(SEARCH("PSA 8",$B16)),8,IF(ISNUMBER(SEARCH("PSA",$B16)),"<9","")))))) | H16: =IF($B16="","",IF($D16>=100,"TIER 2",IF(OR(ISNUMBER(SEARCH("PSA 10",$B16)),ISNUMBER(SEARCH("PSA 9.5",$B16)),ISNUMBER(SEARCH("PSA 9",$B16))),"TIER 3",IF(AND($D16>20,N($E16)>=15),"TIER 1","—")))) -> — | I16: =IF($B16="","",IF($D16>=100,"Premium $100+ (auto)",IF(OR(ISNUMBER(SEARCH("PSA 10",$B16)),ISNUMBER(SEARCH("PSA 9.5",$B16)),ISNUMBER(SEARCH("PSA 9",$B16))),"Graded PSA 9+ (auto)",IF(AND($D16>20,N($E16)>=15),"Hot: $20+ & "&$E16&"/day",IF($D16>20,"$20+ — needs velocity check","Below thresholds"))))) -> Below thresholds | J16: =IF($B16="","",IF(AND($D16>20,$D16<100,NOT(OR(ISNUMBER(SEARCH("PSA 10",$B16)),ISNUMBER(SEARCH("PSA 9.5",$B16)),ISNUMBER(SEARCH("PSA 9",$B16)))),$E16=""),"YES — pull CardHedger",""))
... A4021: 227307171700 | B4021: 2025 Topps Now Aaron Judge Shohei Ohtani MVP Homers Same Inning #239 | C4021: MISC-0002-00003-90757 | D4021: 7 | F4021: =IF($B4021="","",IF(ISNUMBER(SEARCH("PSA",$B4021)),"Yes","No")) -> No | G4021: =IF($B4021="","",IF(ISNUMBER(SEARCH("PSA 10",$B4021)),10,IF(ISNUMBER(SEARCH("PSA 9.5",$B4021)),9.5,IF(ISNUMBER(SEARCH("PSA 9",$B4021)),9,IF(ISNUMBER(SEARCH("PSA 8",$B4021)),8,IF(ISNUMBER(SEARCH("PSA",$B4021)),"<9","")))))) | H4021: =IF($B4021="","",IF($D4021>=100,"TIER 2",IF(OR(ISNUMBER(SEARCH("PSA 10",$B4021)),ISNUMBER(SEARCH("PSA 9.5",$B4021)),ISNUMBER(SEARCH("PSA 9",$B4021))),"TIER 3",IF(AND($D4021>20,N($E4021)>=15),"TIER 1","—")))) -> — | I4021: =IF($B4021="","",IF($D4021>=100,"Premium $100+ (auto)",IF(OR(ISNUMBER(SEARCH("PSA 10",$B4021)),ISNUMBER(SEARCH("PSA 9.5",$B4021)),ISNUMBER(SEARCH("PSA 9",$B4021))),"Graded PSA 9+ (auto)",IF(AND($D4021>20,N($E4021)>=15),"Hot: $20+ & "&$E4021&"/day",IF($D4021>20,"$20+ — needs velocity check","Below thresholds"))))) -> Below thresholds | J4021: =IF($B4021="","",IF(AND($D4021>20,$D4021<100,NOT(OR(ISNUMBER(SEARCH("PSA 10",$B4021)),ISNUMBER(SEARCH("PSA 9.5",$B4021)),ISNUMBER(SEARCH("PSA 9",$B4021)))),$E4021=""),"YES — pull CardHedger",""))
A4022: 227307306880 | B4022: 2021-22 Topps Stadium Club Chrome Uefa Champions League - Lionel Messi #30 Aqua | D4022: 179.99 | F4022: =IF($B4022="","",IF(ISNUMBER(SEARCH("PSA",$B4022)),"Yes","No")) -> No | G4022: =IF($B4022="","",IF(ISNUMBER(SEARCH("PSA 10",$B4022)),10,IF(ISNUMBER(SEARCH("PSA 9.5",$B4022)),9.5,IF(ISNUMBER(SEARCH("PSA 9",$B4022)),9,IF(ISNUMBER(SEARCH("PSA 8",$B4022)),8,IF(ISNUMBER(SEARCH("PSA",$B4022)),"<9","")))))) | H4022: =IF($B4022="","",IF($D4022>=100,"TIER 2",IF(OR(ISNUMBER(SEARCH("PSA 10",$B4022)),ISNUMBER(SEARCH("PSA 9.5",$B4022)),ISNUMBER(SEARCH("PSA 9",$B4022))),"TIER 3",IF(AND($D4022>20,N($E4022)>=15),"TIER 1","—")))) -> TIER 2 | I4022: =IF($B4022="","",IF($D4022>=100,"Premium $100+ (auto)",IF(OR(ISNUMBER(SEARCH("PSA 10",$B4022)),ISNUMBER(SEARCH("PSA 9.5",$B4022)),ISNUMBER(SEARCH("PSA 9",$B4022))),"Graded PSA 9+ (auto)",IF(AND($D4022>20,N($E4022)>=15),"Hot: $20+ & "&$E4022&"/day",IF($D4022>20,"$20+ — needs velocity check","Below thresholds"))))) -> Premium $100+ (auto) | J4022: =IF($B4022="","",IF(AND($D4022>20,$D4022<100,NOT(OR(ISNUMBER(SEARCH("PSA 10",$B4022)),ISNUMBER(SEARCH("PSA 9.5",$B4022)),ISNUMBER(SEARCH("PSA 9",$B4022)))),$E4022=""),"YES — pull CardHedger",""))
A4023: 227307310214 | B4023: Leaf Legend Lionel Messi Exclusive Edition LE-02 Soccer Card 2023 | D4023: 25 | F4023: =IF($B4023="","",IF(ISNUMBER(SEARCH("PSA",$B4023)),"Yes","No")) -> No | G4023: =IF($B4023="","",IF(ISNUMBER(SEARCH("PSA 10",$B4023)),10,IF(ISNUMBER(SEARCH("PSA 9.5",$B4023)),9.5,IF(ISNUMBER(SEARCH("PSA 9",$B4023)),9,IF(ISNUMBER(SEARCH("PSA 8",$B4023)),8,IF(ISNUMBER(SEARCH("PSA",$B4023)),"<9","")))))) | H4023: =IF($B4023="","",IF($D4023>=100,"TIER 2",IF(OR(ISNUMBER(SEARCH("PSA 10",$B4023)),ISNUMBER(SEARCH("PSA 9.5",$B4023)),ISNUMBER(SEARCH("PSA 9",$B4023))),"TIER 3",IF(AND($D4023>20,N($E4023)>=15),"TIER 1","—")))) -> — | I4023: =IF($B4023="","",IF($D4023>=100,"Premium $100+ (auto)",IF(OR(ISNUMBER(SEARCH("PSA 10",$B4023)),ISNUMBER(SEARCH("PSA 9.5",$B4023)),ISNUMBER(SEARCH("PSA 9",$B4023))),"Graded PSA 9+ (auto)",IF(AND($D4023>20,N($E4023)>=15),"Hot: $20+ & "&$E4023&"/day",IF($D4023>20,"$20+ — needs velocity check","Below thresholds"))))) -> $20+ — needs velocity check | J4023: =IF($B4023="","",IF(AND($D4023>20,$D4023<100,NOT(OR(ISNUMBER(SEARCH("PSA 10",$B4023)),ISNUMBER(SEARCH("PSA 9.5",$B4023)),ISNUMBER(SEARCH("PSA 9",$B4023)))),$E4023=""),"YES — pull CardHedger","")) -> YES — pull CardHedger
A4024: 227308339104 | B4024: 2026 Topps Jac Caglianone #138 RC Royals | C4024: MISC-0002-00016-30315 | D4024: 1.99 | F4024: =IF($B4024="","",IF(ISNUMBER(SEARCH("PSA",$B4024)),"Yes","No")) -> No | G4024: =IF($B4024="","",IF(ISNUMBER(SEARCH("PSA 10",$B4024)),10,IF(ISNUMBER(SEARCH("PSA 9.5",$B4024)),9.5,IF(ISNUMBER(SEARCH("PSA 9",$B4024)),9,IF(ISNUMBER(SEARCH("PSA 8",$B4024)),8,IF(ISNUMBER(SEARCH("PSA",$B4024)),"<9","")))))) | H4024: =IF($B4024="","",IF($D4024>=100,"TIER 2",IF(OR(ISNUMBER(SEARCH("PSA 10",$B4024)),ISNUMBER(SEARCH("PSA 9.5",$B4024)),ISNUMBER(SEARCH("PSA 9",$B4024))),"TIER 3",IF(AND($D4024>20,N($E4024)>=15),"TIER 1","—")))) -> — | I4024: =IF($B4024="","",IF($D4024>=100,"Premium $100+ (auto)",IF(OR(ISNUMBER(SEARCH("PSA 10",$B4024)),ISNUMBER(SEARCH("PSA 9.5",$B4024)),ISNUMBER(SEARCH("PSA 9",$B4024))),"Graded PSA 9+ (auto)",IF(AND($D4024>20,N($E4024)>=15),"Hot: $20+ & "&$E4024&"/day",IF($D4024>20,"$20+ — needs velocity check","Below thresholds"))))) -> Below thresholds | J4024: =IF($B4024="","",IF(AND($D4024>20,$D4024<100,NOT(OR(ISNUMBER(SEARCH("PSA 10",$B4024)),ISNUMBER(SEARCH("PSA 9.5",$B4024)),ISNUMBER(SEARCH("PSA 9",$B4024)))),$E4024=""),"YES — pull CardHedger",""))
A4025: 227308339114 | B4025: 2025 Bowman's Best Cam Smith #29 Lazer Refractor 314/350 RC Astros | C4025: MISC-0002-00007-33697 | D4025: 4.79 | F4025: =IF($B4025="","",IF(ISNUMBER(SEARCH("PSA",$B4025)),"Yes","No")) -> No | G4025: =IF($B4025="","",IF(ISNUMBER(SEARCH("PSA 10",$B4025)),10,IF(ISNUMBER(SEARCH("PSA 9.5",$B4025)),9.5,IF(ISNUMBER(SEARCH("PSA 9",$B4025)),9,IF(ISNUMBER(SEARCH("PSA 8",$B4025)),8,IF(ISNUMBER(SEARCH("PSA",$B4025)),"<9","")))))) | H4025: =IF($B4025="","",IF($D4025>=100,"TIER 2",IF(OR(ISNUMBER(SEARCH("PSA 10",$B4025)),ISNUMBER(SEARCH("PSA 9.5",$B4025)),ISNUMBER(SEARCH("PSA 9",$B4025))),"TIER 3",IF(AND($D4025>20,N($E4025)>=15),"TIER 1","—")))) -> — | I4025: =IF($B4025="","",IF($D4025>=100,"Premium $100+ (auto)",IF(OR(ISNUMBER(SEARCH("PSA 10",$B4025)),ISNUMBER(SEARCH("PSA 9.5",$B4025)),ISNUMBER(SEARCH("PSA 9",$B4025))),"Graded PSA 9+ (auto)",IF(AND($D4025>20,N($E4025)>=15),"Hot: $20+ & "&$E4025&"/day",IF($D4025>20,"$20+ — needs velocity check","Below thresholds"))))) -> Below thresholds | J4025: =IF($B4025="","",IF(AND($D4025>20,$D4025<100,NOT(OR(ISNUMBER(SEARCH("PSA 10",$B4025)),ISNUMBER(SEARCH("PSA 9.5",$B4025)),ISNUMBER(SEARCH("PSA 9",$B4025)))),$E4025=""),"YES — pull CardHedger",""))
A4026: 227308339137 | B4026: 2025 Bowman's Best Ketel Marte #62 Refractor Diamondbacks | C4026: MISC-0002-00013-17413 | D4026: 1.99 | F4026: =IF($B4026="","",IF(ISNUMBER(SEARCH("PSA",$B4026)),"Yes","No")) -> No | G4026: =IF($B4026="","",IF(ISNUMBER(SEARCH("PSA 10",$B4026)),10,IF(ISNUMBER(SEARCH("PSA 9.5",$B4026)),9.5,IF(ISNUMBER(SEARCH("PSA 9",$B4026)),9,IF(ISNUMBER(SEARCH("PSA 8",$B4026)),8,IF(ISNUMBER(SEARCH("PSA",$B4026)),"<9","")))))) | H4026: =IF($B4026="","",IF($D4026>=100,"TIER 2",IF(OR(ISNUMBER(SEARCH("PSA 10",$B4026)),ISNUMBER(SEARCH("PSA 9.5",$B4026)),ISNUMBER(SEARCH("PSA 9",$B4026))),"TIER 3",IF(AND($D4026>20,N($E4026)>=15),"TIER 1","—")))) -> — | I4026: =IF($B4026="","",IF($D4026>=100,"Premium $100+ (auto)",IF(OR(ISNUMBER(SEARCH("PSA 10",$B4026)),ISNUMBER(SEARCH("PSA 9.5",$B4026)),ISNUMBER(SEARCH("PSA 9",$B4026))),"Graded PSA 9+ (auto)",IF(AND($D4026>20,N($E4026)>=15),"Hot: $20+ & "&$E4026&"/day",IF($D4026>20,"$20+ — needs velocity check","Below thresholds"))))) -> Below thresholds | J4026: =IF($B4026="","",IF(AND($D4026>20,$D4026<100,NOT(OR(ISNUMBER(SEARCH("PSA 10",$B4026)),ISNUMBER(SEARCH("PSA 9.5",$B4026)),ISNUMBER(SEARCH("PSA 9",$B4026)))),$E4026=""),"YES — pull CardHedger",""))
A4027: 227308339173 | B4027: 2025 Bowman Draft Ike Irish #PP-8 Chrome Prized Prospects Mojo Refractor Orioles | C4027: MISC-0002-00001-61747 | D4027: 1.99 | F4027: =IF($B4027="","",IF(ISNUMBER(SEARCH("PSA",$B4027)),"Yes","No")) -> No | G4027: =IF($B4027="","",IF(ISNUMBER(SEARCH("PSA 10",$B4027)),10,IF(ISNUMBER(SEARCH("PSA 9.5",$B4027)),9.5,IF(ISNUMBER(SEARCH("PSA 9",$B4027)),9,IF(ISNUMBER(SEARCH("PSA 8",$B4027)),8,IF(ISNUMBER(SEARCH("PSA",$B4027)),"<9","")))))) | H4027: =IF($B4027="","",IF($D4027>=100,"TIER 2",IF(OR(ISNUMBER(SEARCH("PSA 10",$B4027)),ISNUMBER(SEARCH("PSA 9.5",$B4027)),ISNUMBER(SEARCH("PSA 9",$B4027))),"TIER 3",IF(AND($D4027>20,N($E4027)>=15),"TIER 1","—")))) -> — | I4027: =IF($B4027="","",IF($D4027>=100,"Premium $100+ (auto)",IF(OR(ISNUMBER(SEARCH("PSA 10",$B4027)),ISNUMBER(SEARCH("PSA 9.5",$B4027)),ISNUMBER(SEARCH("PSA 9",$B4027))),"Graded PSA 9+ (auto)",IF(AND($D4027>20,N($E4027)>=15),"Hot: $20+ & "&$E4027&"/day",IF($D4027>20,"$20+ — needs velocity check","Below thresholds"))))) -> Below thresholds | J4027: =IF($B4027="","",IF(AND($D4027>20,$D4027<100,NOT(OR(ISNUMBER(SEARCH("PSA 10",$B4027)),ISNUMBER(SEARCH("PSA 9.5",$B4027)),ISNUMBER(SEARCH("PSA 9",$B4027)))),$E4027=""),"YES — pull CardHedger",""))
A4028: 227308339348 | B4028: 2026 Topps Collector's Kit Exclusive Francisco Lindor #MLB-4 Rainbow Foil | C4028: MISC-0002-00011-28533 | D4028: 1.99 | F4028: =IF($B4028="","",IF(ISNUMBER(SEARCH("PSA",$B4028)),"Yes","No")) -> No | G4028: =IF($B4028="","",IF(ISNUMBER(SEARCH("PSA 10",$B4028)),10,IF(ISNUMBER(SEARCH("PSA 9.5",$B4028)),9.5,IF(ISNUMBER(SEARCH("PSA 9",$B4028)),9,IF(ISNUMBER(SEARCH("PSA 8",$B4028)),8,IF(ISNUMBER(SEARCH("PSA",$B4028)),"<9","")))))) | H4028: =IF($B4028="","",IF($D4028>=100,"TIER 2",IF(OR(ISNUMBER(SEARCH("PSA 10",$B4028)),ISNUMBER(SEARCH("PSA 9.5",$B4028)),ISNUMBER(SEARCH("PSA 9",$B4028))),"TIER 3",IF(AND($D4028>20,N($E4028)>=15),"TIER 1","—")))) -> — | I4028: =IF($B4028="","",IF($D4028>=100,"Premium $100+ (auto)",IF(OR(ISNUMBER(SEARCH("PSA 10",$B4028)),ISNUMBER(SEARCH("PSA 9.5",$B4028)),ISNUMBER(SEARCH("PSA 9",$B4028))),"Graded PSA 9+ (auto)",IF(AND($D4028>20,N($E4028)>=15),"Hot: $20+ & "&$E4028&"/day",IF($D4028>20,"$20+ — needs velocity check","Below thresholds"))))) -> Below thresholds | J4028: =IF($B4028="","",IF(AND($D4028>20,$D4028<100,NOT(OR(ISNUMBER(SEARCH("PSA 10",$B4028)),ISNUMBER(SEARCH("PSA 9.5",$B4028)),ISNUMBER(SEARCH("PSA 9",$B4028)))),$E4028=""),"YES — pull CardHedger",""))
A4029: 227308339412 | B4029: 2025 Bowman Draft Jared Thomas #BDC-147 Chrome Yellow Geometric Refractor /75 | C4029: MISC-0002-00012-75919 | D4029: 8.99 | F4029: =IF($B4029="","",IF(ISNUMBER(SEARCH("PSA",$B4029)),"Yes","No")) -> No | G4029: =IF($B4029="","",IF(ISNUMBER(SEARCH("PSA 10",$B4029)),10,IF(ISNUMBER(SEARCH("PSA 9.5",$B4029)),9.5,IF(ISNUMBER(SEARCH("PSA 9",$B4029)),9,IF(ISNUMBER(SEARCH("PSA 8",$B4029)),8,IF(ISNUMBER(SEARCH("PSA",$B4029)),"<9","")))))) | H4029: =IF($B4029="","",IF($D4029>=100,"TIER 2",IF(OR(ISNUMBER(SEARCH("PSA 10",$B4029)),ISNUMBER(SEARCH("PSA 9.5",$B4029)),ISNUMBER(SEARCH("PSA 9",$B4029))),"TIER 3",IF(AND($D4029>20,N($E4029)>=15),"TIER 1","—")))) -> — | I4029: =IF($B4029="","",IF($D4029>=100,"Premium $100+ (auto)",IF(OR(ISNUMBER(SEARCH("PSA 10",$B4029)),ISNUMBER(SEARCH("PSA 9.5",$B4029)),ISNUMBER(SEARCH("PSA 9",$B4029))),"Graded PSA 9+ (auto)",IF(AND($D4029>20,N($E4029)>=15),"Hot: $20+ & "&$E4029&"/day",IF($D4029>20,"$20+ — needs velocity check","Below thresholds"))))) -> Below thresholds | J4029: =IF($B4029="","",IF(AND($D4029>20,$D4029<100,NOT(OR(ISNUMBER(SEARCH("PSA 10",$B4029)),ISNUMBER(SEARCH("PSA 9.5",$B4029)),ISNUMBER(SEARCH("PSA 9",$B4029)))),$E4029=""),"YES — pull CardHedger",""))
A4030: 227308339424 | B4030: 2025 Bowman's Best Christian Moore #TP-2 Top Prospects Refractor Angels | C4030: MISC-0002-00015-14735 | D4030: 2.49 | F4030: =IF($B4030="","",IF(ISNUMBER(SEARCH("PSA",$B4030)),"Yes","No")) -> No | G4030: =IF($B4030="","",IF(ISNUMBER(SEARCH("PSA 10",$B4030)),10,IF(ISNUMBER(SEARCH("PSA 9.5",$B4030)),9.5,IF(ISNUMBER(SEARCH("PSA 9",$B4030)),9,IF(ISNUMBER(SEARCH("PSA 8",$B4030)),8,IF(ISNUMBER(SEARCH("PSA",$B4030)),"<9","")))))) | H4030: =IF($B4030="","",IF($D4030>=100,"TIER 2",IF(OR(ISNUMBER(SEARCH("PSA 10",$B4030)),ISNUMBER(SEARCH("PSA 9.5",$B4030)),ISNUMBER(SEARCH("PSA 9",$B4030))),"TIER 3",IF(AND($D4030>20,N($E4030)>=15),"TIER 1","—")))) -> — | I4030: =IF($B4030="","",IF($D4030>=100,"Premium $100+ (auto)",IF(OR(ISNUMBER(SEARCH("PSA 10",$B4030)),ISNUMBER(SEARCH("PSA 9.5",$B4030)),ISNUMBER(SEARCH("PSA 9",$B4030))),"Graded PSA 9+ (auto)",IF(AND($D4030>20,N($E4030)>=15),"Hot: $20+ & "&$E4030&"/day",IF($D4030>20,"$20+ — needs velocity check","Below thresholds"))))) -> Below thresholds | J4030: =IF($B4030="","",IF(AND($D4030>20,$D4030<100,NOT(OR(ISNUMBER(SEARCH("PSA 10",$B4030)),ISNUMBER(SEARCH("PSA 9.5",$B4030)),ISNUMBER(SEARCH("PSA 9",$B4030)))),$E4030=""),"YES — pull CardHedger",""))
A4031: 227308339457 | B4031: 2025 Bowman's Best Luke Keaschall #70 Refractor RC Twins | C4031: MISC-0002-00014-39180 | D4031: 1.99 | F4031: =IF($B4031="","",IF(ISNUMBER(SEARCH("PSA",$B4031)),"Yes","No")) -> No | G4031: =IF($B4031="","",IF(ISNUMBER(SEARCH("PSA 10",$B4031)),10,IF(ISNUMBER(SEARCH("PSA 9.5",$B4031)),9.5,IF(ISNUMBER(SEARCH("PSA 9",$B4031)),9,IF(ISNUMBER(SEARCH("PSA 8",$B4031)),8,IF(ISNUMBER(SEARCH("PSA",$B4031)),"<9","")))))) | H4031: =IF($B4031="","",IF($D4031>=100,"TIER 2",IF(OR(ISNUMBER(SEARCH("PSA 10",$B4031)),ISNUMBER(SEARCH("PSA 9.5",$B4031)),ISNUMBER(SEARCH("PSA 9",$B4031))),"TIER 3",IF(AND($D4031>20,N($E4031)>=15),"TIER 1","—")))) -> — | I4031: =IF($B4031="","",IF($D4031>=100,"Premium $100+ (auto)",IF(OR(ISNUMBER(SEARCH("PSA 10",$B4031)),ISNUMBER(SEARCH("PSA 9.5",$B4031)),ISNUMBER(SEARCH("PSA 9",$B4031))),"Graded PSA 9+ (auto)",IF(AND($D4031>20,N($E4031)>=15),"Hot: $20+ & "&$E4031&"/day",IF($D4031>20,"$20+ — needs velocity check","Below thresholds"))))) -> Below thresholds | J4031: =IF($B4031="","",IF(AND($D4031>20,$D4031<100,NOT(OR(ISNUMBER(SEARCH("PSA 10",$B4031)),ISNUMBER(SEARCH("PSA 9.5",$B4031)),ISNUMBER(SEARCH("PSA 9",$B4031)))),$E4031=""),"YES — pull CardHedger",""))
A4032: 227308339490 | B4032: 2025 Bowman's Best Corbin Carroll #8 Aqua Refractor /199 Diamondbacks | C4032: MISC-0002-00004-49744 | D4032: 3.89 | F4032: =IF($B4032="","",IF(ISNUMBER(SEARCH("PSA",$B4032)),"Yes","No")) -> No | G4032: =IF($B4032="","",IF(ISNUMBER(SEARCH("PSA 10",$B4032)),10,IF(ISNUMBER(SEARCH("PSA 9.5",$B4032)),9.5,IF(ISNUMBER(SEARCH("PSA 9",$B4032)),9,IF(ISNUMBER(SEARCH("PSA 8",$B4032)),8,IF(ISNUMBER(SEARCH("PSA",$B4032)),"<9","")))))) | H4032: =IF($B4032="","",IF($D4032>=100,"TIER 2",IF(OR(ISNUMBER(SEARCH("PSA 10",$B4032)),ISNUMBER(SEARCH("PSA 9.5",$B4032)),ISNUMBER(SEARCH("PSA 9",$B4032))),"TIER 3",IF(AND($D4032>20,N($E4032)>=15),"TIER 1","—")))) -> — | I4032: =IF($B4032="","",IF($D4032>=100,"Premium $100+ (auto)",IF(OR(ISNUMBER(SEARCH("PSA 10",$B4032)),ISNUMBER(SEARCH("PSA 9.5",$B4032)),ISNUMBER(SEARCH("PSA 9",$B4032))),"Graded PSA 9+ (auto)",IF(AND($D4032>20,N($E4032)>=15),"Hot: $20+ & "&$E4032&"/day",IF($D4032>20,"$20+ — needs velocity check","Below thresholds"))))) -> Below thresholds | J4032: =IF($B4032="","",IF(AND($D4032>20,$D4032<100,NOT(OR(ISNUMBER(SEARCH("PSA 10",$B4032)),ISNUMBER(SEARCH("PSA 9.5",$B4032)),ISNUMBER(SEARCH("PSA 9",$B4032)))),$E4032=""),"YES — pull CardHedger",""))
