Workbook

Sheet Start Here
B1: 💎 DFS Card Grader — Operations Kit
B2: Built to work alongside the DFS Card Grader app · dfscards.com
B4: ⚡ HOW THIS WORKBOOK WORKS
B6: 1. Use the DFS Card Grader app | C6: Search any card → get the gem rate → calculate your GO/NO-GO decision
B7: 2. Log grading candidates here | C7: Add cards to the Grading Candidates tab as you find opportunities
B8: 3. Run the ROI Calculator | C8: Open the Grading ROI Calculator tab → enter raw price, gem rate, and PSA 10 avg → get instant GO/NO-GO
B9: 4. Track your submissions | C9: Once you send cards to PSA, log them in the Grading Tracker tab
B10: 5. Update results when graded | C10: When grades come back, update the Grade Returned and Actual Sell Price columns to track real ROI
B12: 💎 GRADING TOOLS
B13: ➤ PSA Fee Schedule | C13: Reference sheet — all 7 PSA grading tiers with fees and eBay cost breakdown
B14: ➤ Grading ROI Calculator | C14: Enter raw price + gem rate + PSA 10 value → instant GO/NO-GO decision
B15: ➤ Grading Tracker | C15: Log every card sent to PSA — track status, grade returned, and actual ROI
B16: ➤ Grading Candidates | C16: Shortlist of cards from your inventory being considered for PSA submission
B18: 📋 OPERATIONS
B19: ➤ Dashboard | C19: Live KPIs — revenue, margin, and sales volume at a glance
B20: ➤ Target Card List | C20: Your buy list — cards to hunt with max buy price and target sell price
B21: ➤ 14-Day Volume Ramp | C21: Day-by-day tactical plan for ramping sales volume
B22: ➤ Sales Log | C22: Every completed sale — date, price, channel, fees, and net margin
B23: ➤ Consignment Tracker | C23: Cards sent to auction houses — DcSports87, PWCC, Probstein — status and payouts
B25: 📦 INVENTORY
B26: ➤ Inventory & Aging | C26: Full inventory with cost basis, days listed, aging flags, and next action
B27: ➤ Lot Evaluator | C27: Pre-buy decision tool — input comp total + target margin to calculate max offer
B28: ➤ DcSports87 May 2026 | C28: Top scored cards for DcSports87 consignment batch
B29: ➤ DcSports87 — Normal Batch | C29: Standard DcSports87 consignment batch — $3–$25 range
B31: 🏈⚾🏀 HEYSTACK PRIORITY
B32: ➤ FB Cards — HeyStack Priority | C32: Top Football cards scored and ranked for HeyStack relisting
B33: ➤ BB Cards — HeyStack Priority | C33: Top Baseball cards scored and ranked for HeyStack relisting
B34: ➤ BK Cards — HeyStack Priority | C34: Top Basketball cards scored and ranked for HeyStack relisting
B36: 💰 FINANCIAL MODELS
B37: ➤ Channel Fees | C37: Live fee calculator — eBay vs HeyStack vs COMC vs consignment
B38: ➤ Capital Velocity | C38: Tracks how fast your working capital is cycling and net profit implications
B39: ➤ Helper ROI | C39: Hiring decision model — quantifies the ROI of bringing on an assistant
B40: ➤ Path to $40k | C40: Month-by-month revenue projection toward your $40k goal
B41: ➤ Stale Action — Market Comps | C41: Market comp research for aging inventory — action urgency by card
B43: © 2025 DFS Cards LLC · 8601 E Palo Verde Dr, Scottsdale AZ 85250 · All rights reserved

Sheet Dashboard
A1: 🏠 Start Here
A2: Your weekly 60-second check-in. Numbers pull from the other tabs.
A4: HEADLINE NUMBERS (from live data)
B5: Direct Sales Gross | D5: Direct Sales Net | F5: Consignment Net | H5: Total Net (all channels)
B6: ='Sales Log'!F3 | D6: ='Sales Log'!J3 | F6: ='Consignment Tracker'!I3 | H6: ='Sales Log'!J3+'Consignment Tracker'!I3
B8: Direct Margin % | D8: Avg Net / Consigned Card | F8: Stale Cards (≥60d) | H8: Capital at Risk (stale)
B9: =IFERROR('Sales Log'!J3/'Sales Log'!F3,"") | D9: =IFERROR('Consignment Tracker'!I3/'Consignment Tracker'!C3,"") | F9: ='Inventory & Aging'!E3 | H9: ='Inventory & Aging'!G3
A12: PROGRESS vs TARGETS
B13: Monthly Net Target (current phase) | E13: 8000
B14: Actual Monthly Net (YTD-indicative) | E14: ='Sales Log'!J3+'Consignment Tracker'!I3
B15: % of Phase Target | E15: =IFERROR(C14/C13,"")
A18: QUICK ACTIONS
B19: → Sales Log: log any sales since last week.
B20: → Consignment Tracker: update any auctions that closed.
B21: → Inventory & Aging: route all STALE-flagged cards to next consignment batch.
B22: → Path to $40k: compare actual net vs this month's milestone.
B23: → Helper ROI: if you haven't hired yet, re-run the calculator — it is the fastest win.

Sheet Target Card List
A1: 🏠 Start Here
A2: 25 NFL + 20 Soccer + 20 Baseball (liquid ≥10 sales/90d) — $8-155 band. WC 2026 LIVE in 6 weeks. 2025 MLB season catalyst active.
E3: TOTALS → | F3: =SUM(F5:F55) | G3: =SUM(G5:G55) | H3: =SUM(H5:H55) | I3: =SUM(I5:I55) | L3: =IFERROR(I3/G3,"")
A4: # | B4: Sport | C4: Player | D4: Card / Variant | E4: Grade / Cond. | F4: Max Buy ($) | G4: Target Sell ($) | H4: Est. Fees ($) | I4: Est. Net ($) | J4: Catalyst / Why | K4: Best Channel | L4: Margin % | M4: In Stock | N4: Your Avg $ | O4: Status
A5: 1 | B5: NFL | C5: Patrick Mahomes | D5: 2017 Panini Prizm #269 RC Silver | E5: Raw NM-M | F5: 35 | G5: 80 | H5: =G5*0.1325 | I5: =G5-H5-F5 | J5: SB contender, top QB | K5: eBay BIN | L5: =IFERROR(I5/G5,"")
A6: 2 | B6: NFL | C6: Ja'Marr Chase | D6: 2021 Panini Prizm #387 RC Silver | E6: Raw NM-M | F6: 20 | G6: 55 | H6: =G6*0.1325 | I6: =G6-H6-F6 | J6: WR1 threat | K6: eBay BIN | L6: =IFERROR(I6/G6,"")
A7: 3 | B7: MLB | C7: Juan Soto | D7: 2018 Topps Chrome #31 RC | E7: Raw NM-M | F7: 18 | G7: 45 | H7: =G7*0.1325 | I7: =G7-H7-F7 | J7: 2025 season catalyst | K7: eBay Auction | L7: =IFERROR(I7/G7,"")
H8: =G8*0.136+0.4+4.5+0.75 | I8: =G8-F8-H8 | L8: =IFERROR(I8/G8,"")
H9: =G9*0.1+0+4.5+0.75 | I9: =G9-F9-H9 | L9: =IFERROR(I9/G9,"")
H10: =G10*0.136+0.4+4.5+0.75 | I10: =G10-F10-H10 | L10: =IFERROR(I10/G10,"")
H11: =G11*0.136+0.4+4.5+0.75 | I11: =G11-F11-H11 | L11: =IFERROR(I11/G11,"")
H12: =G12*0.136+0.4+4.5+0.75 | I12: =G12-F12-H12 | L12: =IFERROR(I12/G12,"")
H13: =G13*0.1+0+4.5+0.75 | I13: =G13-F13-H13 | L13: =IFERROR(I13/G13,"")
H14: =G14*0.136+0.4+4.5+0.75 | I14: =G14-F14-H14 | L14: =IFERROR(I14/G14,"")
H15: =G15*0.136+0.4+4.5+0.75 | I15: =G15-F15-H15 | L15: =IFERROR(I15/G15,"")
H16: =G16*0.136+0.4+4.5+0.75 | I16: =G16-F16-H16 | L16: =IFERROR(I16/G16,"")
H17: =G17*0.1+0+4.5+0.75 | I17: =G17-F17-H17 | L17: =IFERROR(I17/G17,"")
H18: =G18*0.1+0+4.5+0.75 | I18: =G18-F18-H18 | L18: =IFERROR(I18/G18,"")
H19: =G19*0.136+0.4+4.5+0.75 | I19: =G19-F19-H19 | L19: =IFERROR(I19/G19,"")
H20: =G20*0.1+0+4.5+0.75 | I20: =G20-F20-H20 | L20: =IFERROR(I20/G20,"")
H21: =G21*0.1+0+4.5+0.75 | I21: =G21-F21-H21 | L21: =IFERROR(I21/G21,"")
H22: =G22*0.1+0+4.5+0.75 | I22: =G22-F22-H22 | L22: =IFERROR(I22/G22,"")
H23: =G23*0.068+0.4+4.5+0.75 | I23: =G23-F23-H23 | L23: =IFERROR(I23/G23,"")
H24: =G24*0.136+0.4+4.5+0.75 | I24: =G24-F24-H24 | L24: =IFERROR(I24/G24,"")
H25: =G25*0.136+0.4+4.5+0.75 | I25: =G25-F25-H25 | L25: =IFERROR(I25/G25,"")
H26: =G26*0.068+0.4+4.5+0.75 | I26: =G26-F26-H26 | L26: =IFERROR(I26/G26,"")
H27: =G27*0.1+0+4.5+0.75 | I27: =G27-F27-H27 | L27: =IFERROR(I27/G27,"")
H28: =G28*0.136+0.4+4.5+0.75 | I28: =G28-F28-H28 | L28: =IFERROR(I28/G28,"")
H29: =G29*0.1+0+4.5+0.75 | I29: =G29-F29-H29 | L29: =IFERROR(I29/G29,"")
H30: =G30*0.136+0.4+4.5+0.75 | I30: =G30-F30-H30 | L30: =IFERROR(I30/G30,"")
H31: =G31*0.136+0.4+4.5+0.75 | I31: =G31-F31-H31 | L31: =IFERROR(I31/G31,"")
H32: =G32*0.136+0.4+4.5+0.75 | I32: =G32-F32-H32 | L32: =IFERROR(I32/G32,"")
H33: =G33*0.1+0+4.5+0.75 | I33: =G33-F33-H33 | L33: =IFERROR(I33/G33,"")
H34: =G34*0.136+0.4+4.5+0.75 | I34: =G34-F34-H34 | L34: =IFERROR(I34/G34,"")
H35: =G35*0.136+0.4+4.5+0.75 | I35: =G35-F35-H35 | L35: =IFERROR(I35/G35,"")
H36: =G36*0.136+0.4+4.5+0.75 | I36: =G36-F36-H36 | L36: =IFERROR(I36/G36,"")
H37: =G37*0.1+0+4.5+0.75 | I37: =G37-F37-H37 | L37: =IFERROR(I37/G37,"")
H38: =G38*0.136+0.4+4.5+0.75 | I38: =G38-F38-H38 | L38: =IFERROR(I38/G38,"")
H39: =G39*0.1+0+4.5+0.75 | I39: =G39-F39-H39 | L39: =IFERROR(I39/G39,"")
H40: =G40*0.136+0.4+4.5+0.75 | I40: =G40-F40-H40 | L40: =IFERROR(I40/G40,"")
...

Sheet 14-Day Volume Ramp
A1: 🏠 Start Here
A2: Tactical day-by-day plan. Volume comes from listing throughput + pricing discipline + Whatnot pushes.
A4: THE MATH — what has to happen
B5: Metric | C5: Current | D5: Week 1 Target | E5: Week 2 Target | F5: End-State
B6: Cards listed / day | C6: 50 | D6: 70 (+helper) | E6: 90-100 | F6: 100
B7: 30-day sell-through rate | C7: 60% | D7: 65% | E7: 68% | F7: 70%
B8: Cards sold / day (implied) | C8: 30 | D8: 40 | E8: 55 | F8: 65+
B9: Pricing discipline (% of median) | C9: 92% | D9: 90% | E9: 88% | F9: 88%
B10: Whatnot auction streams / week | C10: 0 | D10: 1 (50-80 cards) | E10: 2 (100+ cards) | F10: 2-3
B11: eBay 7-day auction listings / wk | C11: 0 | D11: 30 (aged inv.) | E11: 50+ | F11: 50+
A15: DAY-BY-DAY TACTICAL PLAN
B17: Day | C17: Focus | D17: Tactical Actions | E17: List Target | F17: Sold Target | G17: Whatnot? | H17: Price Rule | I17: Notes
B18: 1 (Mon) | C18: Helper onboarding | D18: Hire helper (10 hrs/wk). Write photo SOP. You list 50, helper observes + lists 10 trial. | E18: 60 | F18: 30 | G18: No | H18: 92% median
B19: 2 (Tue) | C19: Helper solo listing | D19: Helper lists 25 (QA every one). You list 50 + 30 Whatnot auction prep. | E19: 75 | F19: 35 | G19: Prep | H19: 92%
B20: 3 (Wed) | C20: Whatnot stream #1 | D20: Helper lists 30. You prep Whatnot (50 cards). 7-10pm live stream — clear aged inventory. | E20: 80 | F20: 45 | G20: YES | H20: Auction
B21: 4 (Thu) | C21: Recovery + list | D21: Helper lists 35. You list 45 + ship from Whatnot stream. | E21: 80 | F21: 40 | G21: No | H21: 92%
B22: 5 (Fri) | C22: eBay 7-day auctions | D22: Helper lists 40. You post 30 eBay auctions of aged 30+ day inventory at $0.99 start. | E22: 70 | F22: 42 | G22: No | H22: Auction
B23: 6 (Sat) | C23: Source day | D23: Helper off. You list 25 AM then hunt FB/eBay lots 3 hrs (use Lot Evaluator). List buys same day. | E23: 50 | F23: 40 | G23: No | H23: 90%
B24: 7 (Sun) | C24: Whatnot stream #2 | D24: You prep 60 cards. 6-9pm Whatnot stream — mix mid-tier + bulk. | E24: 60 | F24: 55 | G24: YES | H24: Auction
B25: 8 (Mon) | C25: Price cuts + re-list | D25: Helper 40. You re-price everything listed 30+ days: drop to 88%. List 40 new. | E25: 80 | F25: 45 | G25: No | H25: 88% on aged
B26: 9 (Tue) | C26: Helper at full speed | D26: Helper lists 50 (SOP dialed). You list 40. Total output: 90/day. | E26: 90 | F26: 50 | G26: No | H26: 88%
B27: 10 (Wed) | C27: Whatnot + aged cleanup | D27: Helper lists 45. You prep Whatnot (80 cards) — push aged + new. 7-10pm stream. | E27: 80 | F27: 60 | G27: YES | H27: Auction
B28: 11 (Thu) | C28: Consignment batch | D28: Helper lists 45. You pack 40 cards to DcSports87 + 30 to Probstein. List 35. | E28: 80 | F28: 50 | G28: No | H28: 88%
B29: 12 (Fri) | C29: eBay auctions + FB lot push | D29: Helper lists 50. You list 35 + post FB Marketplace bulk lot. Daily shipping. | E29: 85 | F29: 50 | G29: No | H29: 88%
... B31: 14 (Sun) | C31: Whatnot stream #3 + review | D31: Prep 100-card stream. 6-10pm. Post-stream: review KPIs, set Week 3 targets. | E31: 100 | F31: 65 | G31: YES | H31: Auction
B32: 14-DAY TOTAL | E32: =SUM(E18:E31) | F32: =SUM(F18:F31)
A35: THE FIVE LEVERS — ranked by impact
B37: 1. Helper hire (Day 1)
B38: Moves listing capacity from 50 → 90+/day. Single biggest unlock. $600/mo cost for ~$9k revenue add.
B39: 2. Whatnot weekly streams
B40: One 2-3 hour stream moves 50-100 cards. Live price discovery + impulse buying. 3 streams in 14 days = 300+ cards sold.
B41: 3. Pricing discipline
B42: Drop from 92% to 88% of median comp on aged inventory. Accelerates 30-day sell-through by 5-8 pts. Worth more than you think.
B43: 4. eBay 7-day auctions
B44: Auction-format listings with $0.99 start clear aged inventory hard. Run 30-50 aged cards per week as auctions.
B45: 5. Consignment batching
B46: Day 11 send 70 cards out to DcSports87 + Probstein. Frees capital + moves volume while your hands do other things.
A49: REALITY CAVEAT
A50: Hitting 50 sold/day is aggressive from 30/day baseline. Day-by-day targets assume helper hire happens Day 1, Whatnot streams execute on schedule, and pricing discipline is enforced. Realistic completion rate is 80-90% of this plan. If you hit 42-45 sold/day by Day 14, you're still massively ahead of where you started — adjust expectations accordingly.

Sheet Sales Log
A1: 🏠 Start Here
A2: Every direct-sale transaction. Enter new rows at the bottom.
A3: TOTALS → | E3: =SUM(E5:E734) | F3: =SUM(F5:F734) | G3: =SUM(G5:G734) | H3: =SUM(H5:H734) | I3: =SUM(I5:I734) | J3: =SUM(J5:J734) | K3: =IFERROR(J3/F3,"")
A4: Sale Date | B4: Channel | C4: Card Description | D4: Category | E4: Cost Basis ($) | F4: Sell Price ($) | G4: Fees ($) | H4: Shipping Cost ($) | I4: Supplies ($) | J4: Net ($) | K4: Margin % | L4: Days Held
A5: 46037 | B5: eBay | C5: 2024 Panini Prizm Patrick Mahomes RC Base #168 | D5: Football | E5: 18 | F5: 42 | G5: 5.57 | H5: 4.5 | I5: 0.75 | J5: =IFERROR(F5-E5-G5-H5-I5,"") | K5: =IFERROR(J5/F5,"")
A6: 46054 | B6: eBay | C6: 2023 Topps Chrome Corbin Carroll RC #150 | D6: Baseball | E6: 12 | F6: 28 | G6: 3.71 | H6: 4.5 | I6: 0.75 | J6: =IFERROR(F6-E6-G6-H6-I6,"") | K6: =IFERROR(J6/F6,"")
A7: 46091 | B7: Whatnot | C7: 2021 Panini Prizm LeBron James #129 Silver | D7: Basketball | E7: 25 | F7: 58 | G7: 7.69 | H7: 0 | I7: 0.75 | J7: =IFERROR(F7-E7-G7-H7-I7,"") | K7: =IFERROR(J7/F7,"")
J8: =IFERROR(F8-E8-G8-H8-I8,"") | K8: =IFERROR(J8/F8,"")
J9: =IFERROR(F9-E9-G9-H9-I9,"") | K9: =IFERROR(J9/F9,"")
J10: =IFERROR(F10-E10-G10-H10-I10,"") | K10: =IFERROR(J10/F10,"")
J11: =IFERROR(F11-E11-G11-H11-I11,"") | K11: =IFERROR(J11/F11,"")
J12: =IFERROR(F12-E12-G12-H12-I12,"") | K12: =IFERROR(J12/F12,"")
J13: =IFERROR(F13-E13-G13-H13-I13,"") | K13: =IFERROR(J13/F13,"")
J14: =IFERROR(F14-E14-G14-H14-I14,"") | K14: =IFERROR(J14/F14,"")
J15: =IFERROR(F15-E15-G15-H15-I15,"") | K15: =IFERROR(J15/F15,"")
J16: =IFERROR(F16-E16-G16-H16-I16,"") | K16: =IFERROR(J16/F16,"")
J17: =IFERROR(F17-E17-G17-H17-I17,"") | K17: =IFERROR(J17/F17,"")
J18: =IFERROR(F18-E18-G18-H18-I18,"") | K18: =IFERROR(J18/F18,"")
J19: =IFERROR(F19-E19-G19-H19-I19,"") | K19: =IFERROR(J19/F19,"")
... J714: =IFERROR(F714-E714-G714-H714-I714,"") | K714: =IFERROR(J714/F714,"")

Sheet Consignment Tracker
A1: 🏠 Start Here
A2: DcSports87, Probstein, PWCC, MyBrick submissions and net payouts.
A3: TOTALS → | C3: =SUM(C5:C104) | G3: =SUM(G5:G104) | H3: =SUM(H5:H104) | I3: =SUM(I5:I104) | J3: =IFERROR(I3/C3,"")
A4: Submission Date | B4: House | C4: # Cards | D4: Your Est. Value ($) | E4: Card Type Focus | F4: Auction Close Date | G4: Gross Proceeds ($) | H4: House Fees ($) | I4: Net Received ($) | J4: Net / Card ($)
I5: =IFERROR(G5-H5,"") | J5: =IFERROR(I5/C5,"")
I6: =IFERROR(G6-H6,"") | J6: =IFERROR(I6/C6,"")
I7: =IFERROR(G7-H7,"") | J7: =IFERROR(I7/C7,"")
I8: =IFERROR(G8-H8,"") | J8: =IFERROR(I8/C8,"")
I9: =IFERROR(G9-H9,"") | J9: =IFERROR(I9/C9,"")
I10: =IFERROR(G10-H10,"") | J10: =IFERROR(I10/C10,"")
I11: =IFERROR(G11-H11,"") | J11: =IFERROR(I11/C11,"")
I12: =IFERROR(G12-H12,"") | J12: =IFERROR(I12/C12,"")
I13: =IFERROR(G13-H13,"") | J13: =IFERROR(I13/C13,"")
I14: =IFERROR(G14-H14,"") | J14: =IFERROR(I14/C14,"")
I15: =IFERROR(G15-H15,"") | J15: =IFERROR(I15/C15,"")
I16: =IFERROR(G16-H16,"") | J16: =IFERROR(I16/C16,"")
... I104: =IFERROR(G104-H104,"") | J104: =IFERROR(I104/C104,"")
B110: =COUNTIF(B5:B104,A110) | C110: =SUMIF(B5:B104,A110,C5:C104) | D110: =SUMIF(B5:B104,A110,I5:I104) | E110: =IFERROR(D110/C110,"")
B111: =COUNTIF(B5:B104,A111) | C111: =SUMIF(B5:B104,A111,C5:C104) | D111: =SUMIF(B5:B104,A111,I5:I104) | E111: =IFERROR(D111/C111,"")
B112: =COUNTIF(B5:B104,A112) | C112: =SUMIF(B5:B104,A112,C5:C104) | D112: =SUMIF(B5:B104,A112,I5:I104) | E112: =IFERROR(D112/C112,"")
B113: =COUNTIF(B5:B104,A113) | C113: =SUMIF(B5:B104,A113,C5:C104) | D113: =SUMIF(B5:B104,A113,I5:I104) | E113: =IFERROR(D113/C113,"")
B114: =COUNTIF(B5:B104,A114) | C114: =SUMIF(B5:B104,A114,C5:C104) | D114: =SUMIF(B5:B104,A114,I5:I104) | E114: =IFERROR(D114/C114,"")

Sheet DcSports87 May 2026
A1: 🏠 Start Here
A2: Generated: May 03, 2026 | Top 20 by score, all listed > $25 | Est. Total Value: $2,040.17
A4: # | B4: Card Description | C4: Category | D4: Listed Price ($) | E4: Score | F4: Watchers | G4: Market Verdict | H4: DcSports87 Notes
D26: =SUM(D5:D24)

Sheet DcSports87 — Normal Batch
A1: 🏠 Start Here
A2: 75 cards | $3–$25 range | Total listed value: $829.38 | Avg: $11.06/card | All modern (no vintage) | Sorted by auction potential score (highest first)
A3: SCORE = Auto +8 | RC/1st +3 | Chrome/Prizm +2 | Print run (/25=+6, /99=+4, /199=+3, /499=+2, higher=+1) | Patch/Swatch +3 | Jersey/Relic +2 | Price tier ($3-8=+1, $8-15=+2, $15-25=+3) | Watchers = +N each
A5: # | B5: Card Description | C5: Category | D5: Listed ($) | E5: Score | F5: Score Breakdown | G5: Watchers | H5: SKU
D82: =SUM(D6:D80) | E82: =AVERAGE(E6:E80)

Sheet Inventory & Aging
A1: 🏠 Start Here
B2: Track every card you own: when you bought it, when you listed it, and how long it's been sitting. Aging is based on Listed Date — the 60-day clock starts when it goes live.
A3: SUMMARY → | B3: Active listings: | C3: =COUNTIF(H5:H504,"Listed") | D3: Stale (≥60d): | E3: =COUNTIF(J5:J504,"STALE — route now") | F3: Capital at risk ($): | G3: =SUMIFS(F5:F504,J5:J504,"STALE — route now") | H3: Avg days listed: | I3: =IFERROR(AVERAGEIF(H5:H504,"Listed",I5:I504),"—")
A4: Acquired | B4: Listed Date | C4: Source | D4: Card Description | E4: Category | F4: Cost Basis ($) | G4: Listed Price ($) | H4: Status | I4: Days Listed | J4: Aging Flag | K4: Next Action
A5: 46032 | B5: 46034 | C5: eBay | D5: 2024 Panini Prizm Patrick Mahomes #168 RC Silver | E5: Football | F5: 18 | G5: 42 | H5: Listed | I5: =IF(OR(B5="",H5="Sold"),"—",TODAY()-B5) | J5: =IF(OR(B5="",H5="Sold"),"",IF(I5="—","",IF(I5>=60,"STALE — route now",IF(I5>=30,"Aging — watch",IF(I5>=0,"Fresh",""))))) | K5: =IF(J5="STALE — route now","→ Send to consignment batch",IF(J5="Aging — watch","→ Consider 10% price drop",IF(J5="Fresh","→ Hold & monitor","")))
A6: 46058 | B6: 46061 | C6: FB Lot | D6: 2023 Bowman Chrome Corbin Carroll Auto #CPA-CC RC | E6: Baseball | F6: 22 | G6: 55 | H6: Listed | I6: =IF(OR(B6="",H6="Sold"),"—",TODAY()-B6) | J6: =IF(OR(B6="",H6="Sold"),"",IF(I6="—","",IF(I6>=60,"STALE — route now",IF(I6>=30,"Aging — watch",IF(I6>=0,"Fresh",""))))) | K6: =IF(J6="STALE — route now","→ Send to consignment batch",IF(J6="Aging — watch","→ Consider 10% price drop",IF(J6="Fresh","→ Hold & monitor","")))
A7: 46082 | B7: 46084 | C7: Whatnot | D7: 2024 Topps Chrome Fernando Tatis Jr. #100 Gold Ref /50 | E7: Baseball | F7: 30 | G7: 75 | H7: Listed | I7: =IF(OR(B7="",H7="Sold"),"—",TODAY()-B7) | J7: =IF(OR(B7="",H7="Sold"),"",IF(I7="—","",IF(I7>=60,"STALE — route now",IF(I7>=30,"Aging — watch",IF(I7>=0,"Fresh",""))))) | K7: =IF(J7="STALE — route now","→ Send to consignment batch",IF(J7="Aging — watch","→ Consider 10% price drop",IF(J7="Fresh","→ Hold & monitor","")))
I8: =IF(OR(B8="",H8="Sold"),"—",TODAY()-B8) | J8: =IF(OR(B8="",H8="Sold"),"",IF(I8="—","",IF(I8>=60,"STALE — route now",IF(I8>=30,"Aging — watch",IF(I8>=0,"Fresh",""))))) | K8: =IF(J8="STALE — route now","→ Send to consignment batch",IF(J8="Aging — watch","→ Consider 10% price drop",IF(J8="Fresh","→ Hold & monitor","")))
I9: =IF(OR(B9="",H9="Sold"),"—",TODAY()-B9) | J9: =IF(OR(B9="",H9="Sold"),"",IF(I9="—","",IF(I9>=60,"STALE — route now",IF(I9>=30,"Aging — watch",IF(I9>=0,"Fresh",""))))) | K9: =IF(J9="STALE — route now","→ Send to consignment batch",IF(J9="Aging — watch","→ Consider 10% price drop",IF(J9="Fresh","→ Hold & monitor","")))
I11: =IF(OR(B11="",H11="Sold"),"—",TODAY()-B11) | J11: =IF(OR(B11="",H11="Sold"),"",IF(I11="—","",IF(I11>=60,"STALE — route now",IF(I11>=30,"Aging — watch",IF(I11>=0,"Fresh",""))))) | K11: =IF(J11="STALE — route now","→ Send to consignment batch",IF(J11="Aging — watch","→ Consider 10% price drop",IF(J11="Fresh","→ Hold & monitor","")))
I12: =IF(OR(B12="",H12="Sold"),"—",TODAY()-B12) | J12: =IF(OR(B12="",H12="Sold"),"",IF(I12="—","",IF(I12>=60,"STALE — route now",IF(I12>=30,"Aging — watch",IF(I12>=0,"Fresh",""))))) | K12: =IF(J12="STALE — route now","→ Send to consignment batch",IF(J12="Aging — watch","→ Consider 10% price drop",IF(J12="Fresh","→ Hold & monitor","")))
I13: =IF(OR(B13="",H13="Sold"),"—",TODAY()-B13) | J13: =IF(OR(B13="",H13="Sold"),"",IF(I13="—","",IF(I13>=60,"STALE — route now",IF(I13>=30,"Aging — watch",IF(I13>=0,"Fresh",""))))) | K13: =IF(J13="STALE — route now","→ Send to consignment batch",IF(J13="Aging — watch","→ Consider 10% price drop",IF(J13="Fresh","→ Hold & monitor","")))
I14: =IF(OR(B14="",H14="Sold"),"—",TODAY()-B14) | J14: =IF(OR(B14="",H14="Sold"),"",IF(I14="—","",IF(I14>=60,"STALE — route now",IF(I14>=30,"Aging — watch",IF(I14>=0,"Fresh",""))))) | K14: =IF(J14="STALE — route now","→ Send to consignment batch",IF(J14="Aging — watch","→ Consider 10% price drop",IF(J14="Fresh","→ Hold & monitor","")))
I15: =IF(OR(B15="",H15="Sold"),"—",TODAY()-B15) | J15: =IF(OR(B15="",H15="Sold"),"",IF(I15="—","",IF(I15>=60,"STALE — route now",IF(I15>=30,"Aging — watch",IF(I15>=0,"Fresh",""))))) | K15: =IF(J15="STALE — route now","→ Send to consignment batch",IF(J15="Aging — watch","→ Consider 10% price drop",IF(J15="Fresh","→ Hold & monitor","")))
I16: =IF(OR(B16="",H16="Sold"),"—",TODAY()-B16) | J16: =IF(OR(B16="",H16="Sold"),"",IF(I16="—","",IF(I16>=60,"STALE — route now",IF(I16>=30,"Aging — watch",IF(I16>=0,"Fresh",""))))) | K16: =IF(J16="STALE — route now","→ Send to consignment batch",IF(J16="Aging — watch","→ Consider 10% price drop",IF(J16="Fresh","→ Hold & monitor","")))
I17: =IF(OR(B17="",H17="Sold"),"—",TODAY()-B17) | J17: =IF(OR(B17="",H17="Sold"),"",IF(I17="—","",IF(I17>=60,"STALE — route now",IF(I17>=30,"Aging — watch",IF(I17>=0,"Fresh",""))))) | K17: =IF(J17="STALE — route now","→ Send to consignment batch",IF(J17="Aging — watch","→ Consider 10% price drop",IF(J17="Fresh","→ Hold & monitor","")))
I18: =IF(OR(B18="",H18="Sold"),"—",TODAY()-B18) | J18: =IF(OR(B18="",H18="Sold"),"",IF(I18="—","",IF(I18>=60,"STALE — route now",IF(I18>=30,"Aging — watch",IF(I18>=0,"Fresh",""))))) | K18: =IF(J18="STALE — route now","→ Send to consignment batch",IF(J18="Aging — watch","→ Consider 10% price drop",IF(J18="Fresh","→ Hold & monitor","")))
I19: =IF(OR(B19="",H19="Sold"),"—",TODAY()-B19) | J19: =IF(OR(B19="",H19="Sold"),"",IF(I19="—","",IF(I19>=60,"STALE — route now",IF(I19>=30,"Aging — watch",IF(I19>=0,"Fresh",""))))) | K19: =IF(J19="STALE — route now","→ Send to consignment batch",IF(J19="Aging — watch","→ Consider 10% price drop",IF(J19="Fresh","→ Hold & monitor","")))
I20: =IF(OR(B20="",H20="Sold"),"—",TODAY()-B20) | J20: =IF(OR(B20="",H20="Sold"),"",IF(I20="—","",IF(I20>=60,"STALE — route now",IF(I20>=30,"Aging — watch",IF(I20>=0,"Fresh",""))))) | K20: =IF(J20="STALE — route now","→ Send to consignment batch",IF(J20="Aging — watch","→ Consider 10% price drop",IF(J20="Fresh","→ Hold & monitor","")))
... I504: =IF(OR(B504="",H504="Sold"),"—",TODAY()-B504) | J504: =IF(OR(B504="",H504="Sold"),"",IF(I504="—","",IF(I504>=60,"STALE — route now",IF(I504>=30,"Aging — watch",IF(I504>=0,"Fresh",""))))) | K504: =IF(J504="STALE — route now","→ Send to consignment batch",IF(J504="Aging — watch","→ Consider 10% price drop",IF(J504="Fresh","→ Hold & monitor","")))

Sheet FB Cards — HeyStack Priority
A1: 🏠 Start Here
A2: Scored by player tier + auto/patch/print run/PSA/price/watchers | Today: May 03, 2026 | 233 total Football cards in inventory
A3: PRIORITY ACTIONS
A4: Rank | B4: Priority Action | C4: Card Description | D4: SKU | E4: Price ($) | F4: Score | G4: Player Tier | H4: Days Listed | I4: Aging Status | J4: Watchers | K4: Has 90d Sales? | L4: Notes

Sheet BB Cards — HeyStack Priority
A1: 🏠 Start Here
A2: Scored by player tier + auto/patch/print run/PSA/price/watchers | Today: May 03, 2026 | 1643 total Baseball cards in inventory
A3: PRIORITY ACTIONS
A4: Rank | B4: Priority Action | C4: Card Description | D4: SKU | E4: Price ($) | F4: Score | G4: Player Tier | H4: Days Listed | I4: Aging Status | J4: Watchers | K4: Has 90d Sales? | L4: Notes

Sheet BK Cards — HeyStack Priority
A1: 🏠 Start Here
A2: Scored by player tier + auto/patch/print run/PSA/price/watchers | Today: May 03, 2026 | 137 total Basketball cards in inventory
A3: PRIORITY ACTIONS
A4: Rank | B4: Priority Action | C4: Card Description | D4: SKU | E4: Price ($) | F4: Score | G4: Player Tier | H4: Days Listed | I4: Aging Status | J4: Watchers | K4: Has 90d Sales? | L4: Notes

Sheet Lot Evaluator
A1: 🏠 Start Here
A2: Run this BEFORE every lot buying decision. Input comp total + target margin → max offer.
A4: INPUTS (edit blue cells) | E4: CALCULATIONS & MAX OFFER
B5: Total comp value of lot ($) | C5: 1000 | E5: Expected gross proceeds ($) | F5: =C5*C6
B6: Expected sell-through rate (%) | C6: 0.75 | E6: Expected fees ($) | F6: =F5*C7
B7: Your average fee rate (%) | C7: 0.135 | E7: Expected shipping cost ($) | F7: =C8*C10*C6
B8: Avg shipping cost / sale ($) | C8: 4.5 | E8: Expected supplies cost ($) | F8: =C9*C10
B9: Avg supplies cost / sale ($) | C9: 0.75 | E9: Net before COGS ($) | F9: =F5-F6-F7-F8
B10: Estimated # cards | C10: 25 | E10: Dollar margin target on net ($) | F10: =F9*C11
B11: Your target NET margin (%) | C11: 0.35 | E11: MAX OFFER for lot ($) | F11: =F9-F10
A14: DECISION RULE
A15: • If ASKING PRICE ≤ MAX OFFER → BUY. You will hit your target margin.
A16: • If ASKING PRICE is 10-15% above MAX OFFER → counter-offer at MAX OFFER × 0.95 and walk if rejected.
A17: • If ASKING PRICE is >15% above MAX OFFER → WALK. The deal doesn't math — don't let FOMO override the model.
A18: • If lot includes uncertain raw high-grade cards, discount comp total by 20% to reflect grading risk before running.

Sheet Channel Fees
A1: 🏠 Start Here
A2: Live calculator + price-point table + routing rules. Verified fees as of April 2026.
A4: LIVE CALCULATOR — Enter a sale price, see net at each channel
B5: Sale price ($) | C5: 100 | D5: ← Change this cell to model any sale price
B7: Channel | C7: Commission % | D7: Per-Order Fee | E7: Pmt Processing % | F7: Total Fees ($) | G7: Net to You ($) | H7: Effective Fee %
B8: eBay (standard) | C8: 0.136 | D8: 0.4 | E8: 0 | F8: =$C$5*C8+D8+$C$5*E8 | G8: =$C$5-F8 | H8: =IFERROR(F8/$C$5,"") | I8: Default — broadest buyer pool
B9: eBay (singles $1,000+) | C9: 0.068 | D9: 0.4 | E9: 0 | F9: =$C$5*C9+D9+$C$5*E9 | G9: =$C$5-F9 | H9: =IFERROR(F9/$C$5,"") | I9: Auto-applied promo on $1k+ singles
B10: Whatnot | C10: 0.08 | D10: 0.3 | E10: 0.029 | F10: =$C$5*C10+D10+$C$5*E10 | G10: =$C$5-F10 | H10: =IFERROR(F10/$C$5,"") | I10: Cap on commission >$1,500 of single sale
B11: COLLX | C11: 0.1 | D11: 0 | E11: 0 | F11: =$C$5*C11+D11+$C$5*E11 | G11: =$C$5-F11 | H11: =IFERROR(F11/$C$5,"") | I11: Fee includes processing
B12: FB Marketplace (online ship) | C12: 0.05 | D12: 0 | E12: 0 | F12: =$C$5*C12+D12+$C$5*E12 | G12: =$C$5-F12 | H12: =IFERROR(F12/$C$5,"") | I12: Estimate — varies by transaction
B13: FB Marketplace (local cash) | C13: 0 | D13: 0 | E13: 0 | F13: =$C$5*C13+D13+$C$5*E13 | G13: =$C$5-F13 | H13: =IFERROR(F13/$C$5,"") | I13: Zero fees, but limited buyer pool
B14: DcSports87 (consignment) | C14: 0.18 | D14: 0 | E14: 0 | F14: =$C$5*C14+D14+$C$5*E14 | G14: =$C$5-F14 | H14: =IFERROR(F14/$C$5,"") | I14: Verify your actual rate per agreement
B15: Probstein (consignment) | C15: 0.2 | D15: 0 | E15: 0 | F15: =$C$5*C15+D15+$C$5*E15 | G15: =$C$5-F15 | H15: =IFERROR(F15/$C$5,"") | I15: Tiered — verify actual
B16: PWCC (vault auction est.) | C16: 0.2 | D16: 0 | E16: 0 | F16: =$C$5*C16+D16+$C$5*E16 | G16: =$C$5-F16 | H16: =IFERROR(F16/$C$5,"") | I16: Plus storage fees if vaulted
A19: NET TO YOU AT COMMON PRICE POINTS
B21: Channel | C21: $10 | D21: $25 | E21: $50 | F21: $100 | G21: $200 | H21: $500 | I21: $1000
B22: eBay (standard) | C22: =10-(10*$C$8+$D$8+10*$E$8) | D22: =25-(25*$C$8+$D$8+25*$E$8) | E22: =50-(50*$C$8+$D$8+50*$E$8) | F22: =100-(100*$C$8+$D$8+100*$E$8) | G22: =200-(200*$C$8+$D$8+200*$E$8) | H22: =500-(500*$C$8+$D$8+500*$E$8) | I22: =1000-(1000*$C$8+$D$8+1000*$E$8)
B23: eBay (singles $1,000+) | C23: =10-(10*$C$9+$D$9+10*$E$9) | D23: =25-(25*$C$9+$D$9+25*$E$9) | E23: =50-(50*$C$9+$D$9+50*$E$9) | F23: =100-(100*$C$9+$D$9+100*$E$9) | G23: =200-(200*$C$9+$D$9+200*$E$9) | H23: =500-(500*$C$9+$D$9+500*$E$9) | I23: =1000-(1000*$C$9+$D$9+1000*$E$9)
B24: Whatnot | C24: =10-(10*$C$10+$D$10+10*$E$10) | D24: =25-(25*$C$10+$D$10+25*$E$10) | E24: =50-(50*$C$10+$D$10+50*$E$10) | F24: =100-(100*$C$10+$D$10+100*$E$10) | G24: =200-(200*$C$10+$D$10+200*$E$10) | H24: =500-(500*$C$10+$D$10+500*$E$10) | I24: =1000-(1000*$C$10+$D$10+1000*$E$10)
B25: COLLX | C25: =10-(10*$C$11+$D$11+10*$E$11) | D25: =25-(25*$C$11+$D$11+25*$E$11) | E25: =50-(50*$C$11+$D$11+50*$E$11) | F25: =100-(100*$C$11+$D$11+100*$E$11) | G25: =200-(200*$C$11+$D$11+200*$E$11) | H25: =500-(500*$C$11+$D$11+500*$E$11) | I25: =1000-(1000*$C$11+$D$11+1000*$E$11)
B26: FB Marketplace (online ship) | C26: =10-(10*$C$12+$D$12+10*$E$12) | D26: =25-(25*$C$12+$D$12+25*$E$12) | E26: =50-(50*$C$12+$D$12+50*$E$12) | F26: =100-(100*$C$12+$D$12+100*$E$12) | G26: =200-(200*$C$12+$D$12+200*$E$12) | H26: =500-(500*$C$12+$D$12+500*$E$12) | I26: =1000-(1000*$C$12+$D$12+1000*$E$12)
B27: FB Marketplace (local cash) | C27: =10-(10*$C$13+$D$13+10*$E$13) | D27: =25-(25*$C$13+$D$13+25*$E$13) | E27: =50-(50*$C$13+$D$13+50*$E$13) | F27: =100-(100*$C$13+$D$13+100*$E$13) | G27: =200-(200*$C$13+$D$13+200*$E$13) | H27: =500-(500*$C$13+$D$13+500*$E$13) | I27: =1000-(1000*$C$13+$D$13+1000*$E$13)
B28: DcSports87 (consignment) | C28: =10-(10*$C$14+$D$14+10*$E$14) | D28: =25-(25*$C$14+$D$14+25*$E$14) | E28: =50-(50*$C$14+$D$14+50*$E$14) | F28: =100-(100*$C$14+$D$14+100*$E$14) | G28: =200-(200*$C$14+$D$14+200*$E$14) | H28: =500-(500*$C$14+$D$14+500*$E$14) | I28: =1000-(1000*$C$14+$D$14+1000*$E$14)
B29: Probstein (consignment) | C29: =10-(10*$C$15+$D$15+10*$E$15) | D29: =25-(25*$C$15+$D$15+25*$E$15) | E29: =50-(50*$C$15+$D$15+50*$E$15) | F29: =100-(100*$C$15+$D$15+100*$E$15) | G29: =200-(200*$C$15+$D$15+200*$E$15) | H29: =500-(500*$C$15+$D$15+500*$E$15) | I29: =1000-(1000*$C$15+$D$15+1000*$E$15)
B30: PWCC (vault auction est.) | C30: =10-(10*$C$16+$D$16+10*$E$16) | D30: =25-(25*$C$16+$D$16+25*$E$16) | E30: =50-(50*$C$16+$D$16+50*$E$16) | F30: =100-(100*$C$16+$D$16+100*$E$16) | G30: =200-(200*$C$16+$D$16+200*$E$16) | H30: =500-(500*$C$16+$D$16+500*$E$16) | I30: =1000-(1000*$C$16+$D$16+1000*$E$16)
A33: ROUTING DECISION RULES — which channel for which card
B35: Card Type | E35: Best Primary Channel | G35: Why | I35: Backup
B36: Hot modern rookies / chase autos ($50-500) | E36: eBay | G36: Broad buyer pool, fast price discovery, buyers will pay premium despite fees | I36: Whatnot auction if hot player
B37: Mid-tier modern singles ($15-150) | E37: COLLX (primary), eBay (secondary) | G37: COLLX 10% all-in vs eBay ~14%; ~3-4 pts of margin saved on this volume tier | I37: eBay if no movement in 14d
B38: Vintage HOF graded ($500+) | E38: PWCC / Probstein auction | G38: Premium buyer base; auction format extracts max value | I38: eBay BIN with promotion
B39: Bulk lots / commons (50+ cards) | E39: FB Marketplace (local) or COLLX bulk | G39: eBay fees crush low-margin bulk; local cash = zero fees | I39: Whatnot lot break
B40: Quick-cash / time-sensitive | E40: Whatnot live auction | G40: Real-time price discovery, immediate sale | I40: eBay Best Offer accepted
B41: Stale 60+ day inventory | E41: DcSports87 + rotate | G41: Already trained channel; consignment frees capital + your hands | I41: Probstein for variety
B42: Low-confidence sourcing (uncertain comp) | E42: Whatnot or COLLX auction | G42: Market sets price; you don't have to guess | I42: —
B43: Personal pickup deals (>$50/card) | E43: COLLX direct message | G43: Strong collector community; lower fees on direct deals | I43: Local meet via FB
A46: BOTTOM-LINE TAKEAWAY
A47: • COLLX saves ~3-4 percentage points on direct-sale fees vs eBay. At $80k/mo gross, routing 30% to COLLX = ~$700-1,200/mo straight to net.
A48: • COLLX's tradeoff is a smaller buyer base — sell-through is slower (typical: 1-3 weeks vs eBay 3-10 days for hot cards). Use COLLX for cards where you can wait.
A49: • DON'T abandon eBay for hot/high-velocity cards — eBay's ~13.6% fee is more than offset by the price premium buyers pay there for in-demand items.
A50: • Cross-listing tools (Vendoo, List Perfectly) increasingly support COLLX — list once, route to multiple. Worth the $30-50/mo subscription at your scale.
...

Sheet Capital Velocity
A1: 🏠 Start Here
A2: How fast your working capital is cycling, and what it implies for net profit.
A4: CURRENT STATE — editable blue inputs
B5: Working capital ($) | C5: 20000
B6: Avg net margin % | C6: 0.3
B7: Current monthly turns | C7: 2
B8: Implied monthly gross ($) | C8: =C5*C7
B9: Implied monthly net ($) | C9: =C8*C6
A11: SCENARIO GRID — Monthly net at different (margin × turns)
B12: Turns / month → | C12: 1.5 | D12: 2 | E12: 2.5 | F12: 3 | G12: 3.5
B13: 0.2 | C13: =$C$5*1.5*0.2 | D13: =$C$5*2*0.2 | E13: =$C$5*2.5*0.2 | F13: =$C$5*3*0.2 | G13: =$C$5*3.5*0.2
B14: 0.25 | C14: =$C$5*1.5*0.25 | D14: =$C$5*2*0.25 | E14: =$C$5*2.5*0.25 | F14: =$C$5*3*0.25 | G14: =$C$5*3.5*0.25
B15: 0.3 | C15: =$C$5*1.5*0.3 | D15: =$C$5*2*0.3 | E15: =$C$5*2.5*0.3 | F15: =$C$5*3*0.3 | G15: =$C$5*3.5*0.3
B16: 0.35 | C16: =$C$5*1.5*0.35 | D16: =$C$5*2*0.35 | E16: =$C$5*2.5*0.35 | F16: =$C$5*3*0.35 | G16: =$C$5*3.5*0.35
B17: 0.4 | C17: =$C$5*1.5*0.4 | D17: =$C$5*2*0.4 | E17: =$C$5*2.5*0.4 | F17: =$C$5*3*0.4 | G17: =$C$5*3.5*0.4
B18: 0.45 | C18: =$C$5*1.5*0.45 | D18: =$C$5*2*0.45 | E18: =$C$5*2.5*0.45 | F18: =$C$5*3*0.45 | G18: =$C$5*3.5*0.45
B21: Target: $40,000/mo net. Find that dollar value in the grid above. To hit $40k with $20k capital, you need either 2.5x turns @ 40% margin OR 3.5x turns @ 30% margin. Either requires the consignment pivot + capital growth over 6 months.

Sheet Helper ROI
A1: 🏠 Start Here
A2: Quantifies the hiring decision. Change blue inputs; model recalculates.
A4: INPUTS — edit blue cells | E4: OUTPUTS
B5: Hours per week | C5: 10 | E5: Weekly cost ($) | F5: =C5*C6
B6: Hourly rate ($) | C6: 15 | E6: Monthly cost ($) | F6: =F5*C10
B7: Listings per hour (helper avg) | C7: 15 | E7: Weekly listings produced | F7: =C5*C7
B8: Your avg net per direct-sale card ($) | C8: 4 | E8: Monthly listings | F8: =F7*C10
B9: Sell-through rate (%) | C9: 0.6 | E9: Expected sales per month | F9: =F8*C9
B10: Weeks per month | C10: 4.3 | E10: Expected net revenue / month ($) | F10: =F9*C8
B11: Ramp-up factor (month 1 only, %) | C11: 0.6 | E11: NET CONTRIBUTION / month (ongoing) | F11: =F10-F6
E12: NET CONTRIBUTION / month (month 1) | F12: =(F10*C11)-F6
E13: ROI multiple (ongoing) | F13: =IFERROR(F10/F6,"")
A15: DECISION RULE
A16: • If NET CONTRIBUTION (ongoing) > $1,500/mo → hire immediately. Your time is worth more than the wage.
A17: • If NET CONTRIBUTION < $500/mo → re-examine: are your listings/hour assumption or avg net too low?
A18: • Start at 10 hrs/wk with weekly QA. Scale to 15–20 hrs/wk once SOP is proven (Month 2+).
A19: • Budget separately for shipping/packing helper (3–4 hrs/wk) once listing throughput exceeds 150 cards/wk.

Sheet Path to $40k
A1: 🏠 Start Here
A2: Month-by-month projection with adjustable assumptions.
B4: Assumption | C4: Month 1 | D4: Month 2 | E4: Month 3 | F4: Month 4 | G4: Month 5 | H4: Month 6 | I4: Month 7 | J4: Month 8 | K4: Month 9
B5: Working capital (start of month, $) | C5: 20000 | D5: 22000 | E5: 25000 | F5: 29000 | G5: 33000 | H5: 37000 | I5: 41000 | J5: 45000 | K5: 48000
B6: Monthly turns | C6: 2 | D6: 2.2 | E6: 2.5 | F6: 2.8 | G6: 3 | H6: 3.2 | I6: 3.3 | J6: 3.4 | K6: 3.5
B7: Avg net margin % | C7: 0.3 | D7: 0.31 | E7: 0.32 | F7: 0.34 | G7: 0.36 | H7: 0.38 | I7: 0.39 | J7: 0.4 | K7: 0.4
B8: Projected monthly gross ($) | C8: =C5*C6 | D8: =D5*D6 | E8: =E5*E6 | F8: =F5*F6 | G8: =G5*G6 | H8: =H5*H6 | I8: =I5*I6 | J8: =J5*J6 | K8: =K5*K6
B9: Projected monthly NET ($) | C9: =C8*C7 | D9: =D8*D7 | E9: =E8*E7 | F9: =F8*F7 | G9: =G8*G7 | H9: =H8*H7 | I9: =I8*I7 | J9: =J8*J7 | K9: =K8*K7
B10: Gap to $40k target ($) | C10: =40000-C9 | D10: =40000-D9 | E10: =40000-E9 | F10: =40000-F9 | G10: =40000-G9 | H10: =40000-H9 | I10: =40000-I9 | J10: =40000-J9 | K10: =40000-K9
B11: % of $40k target achieved | C11: =C9/40000 | D11: =D9/40000 | E11: =E9/40000 | F11: =F9/40000 | G11: =G9/40000 | H11: =H9/40000 | I11: =I9/40000 | J11: =J9/40000 | K11: =K9/40000
A13: Milestones (Month-End)
B14: Cards listed / week (helper + you) | C14: 200 | D14: 275 | E14: 350 | F14: 450 | G14: 525 | H14: 600 | I14: 700 | J14: 775 | K14: 850
B15: Cards consigned / week (all houses) | C15: 25 | D15: 35 | E15: 45 | F15: 55 | G15: 65 | H15: 75 | I15: 85 | J15: 95 | K15: 100
B16: Avg cost basis / card ($) | C16: 8 | D16: 10 | E16: 13 | F16: 16 | G16: 18 | H16: 20 | I16: 22 | J16: 24 | K16: 25
B17: % of gross from mid+premium tier | C17: 0.2 | D17: 0.26 | E17: 0.33 | F17: 0.4 | G17: 0.45 | H17: 0.5 | I17: 0.53 | J17: 0.56 | K17: 0.58
B19: HOW TO USE THIS MODEL
B20: • The three YELLOW-highlighted rows (working capital, turns, margin) drive the whole model. Adjust any of them to see impact.
B21: • Working capital grows via 60% net reinvestment — if you reinvest less, slow the row 5 progression.
B22: • If you're behind target in any month, the first lever to pull is TURNS (consignment-heavy). Margin takes longer to move.
B23: • Month 6-7 is the realistic earliest window to cross $40k/mo NET at this starting capital and with strict reinvestment.
B24: • If a capital injection happens (partner, loan, mentor buyout purchase), update row 5 and the whole model reflects it.

Sheet Stale Action — Market Comps
A1: 🏠 Start Here
A2: Research Date: May 3, 2026 | Goal: Clear aging inventory this week to make room for new arrivals | Bold = IMMEDIATE ACTION
A3: 🔴 DROP NOW | C3: 🟠 OVERPRICED | E3: 🟡 FAIR / STUCK | G3: 🟢 UNDERPRICED | I3: 🔵 CONSIGN DC87 | K3: ⚪ HOLD
A4: Card Description | B4: Listed $ | C4: Days Listed | D4: Comp Range (Sold) | E4: Market Verdict | F4: Status | G4: Fast-Sell Price | H4: Channel | I4: Action Priority | J4: Notes

Sheet PSA Fee Schedule
A1: PSA Grading Fee Schedule — 2025
A3: Tier | B3: Turnaround | C3: Fee ($) | D3: eBay Fee (13.25%) | E3: Notes
A4: Value Bulk | B4: ~75 days | C4: 32.99 | D4: =C4*0.1325 | E4: Non-membership
A5: Value Plus | B5: ~45 days | C5: 49.99 | D5: =C5*0.1325 | E5: Non-membership
A6: Value Max | B6: ~35 days | C6: 64.99 | D6: =C6*0.1325 | E6: Non-membership
A7: Regular | B7: ~25 days | C7: 79.99 | D7: =C7*0.1325 | E7: Non-membership
A8: Express | B8: ~15 days | C8: 149 | D8: =C8*0.1325 | E8: Non-membership
A9: Super Express | B9: ~7 days | C9: 299 | D9: =C9*0.1325 | E9: Non-membership
A10: Walk-Through | B10: ~7 days ($10k insured) | C10: 599 | D10: =C10*0.1325 | E10: Non-membership
A11: eBay final value fee: 13.25% of sale price

Sheet Grading ROI Calculator
A1: Grading ROI Calculator
A2: INPUTS
A4: Raw Buy Price ($) | B4: 50
A5: PSA Tier | B5: Value Bulk
A6: PSA Fee ($) | B6: 32.99 | C6: Enter fee from "PSA Fee Schedule" tab
A7: Gem Rate (%) | B7: 50
A8: PSA 10 Avg Price ($) | B8: 0
A9: ROI Target (×) | B9: 4
A11: OUTPUTS
A12: eBay Fee ($) | B12: =B8*0.1325
A13: Target PSA 10 Price ($) | B13: =(B4*B9+B6)/(1-0.1325)
A14: Est. Net Profit ($) | B14: =B8*(1-0.1325)-B6-B4
A15: Est. ROI (%) | B15: =IF(B4>0,(B14/B4)*100,0)
A16: GO / NO-GO | B16: =IF(B7<40,"❌ NO-GO — Gem rate below 40% floor",IF(B8>=B13,"✅ GO — Clears target price","❌ NO-GO — Price below target"))
A18: 4× ROI formula: (Raw Cost × ROI Target + PSA Fee) ÷ (1 − 0.1325)

Sheet Grading Tracker
A1: Grading Tracker — PSA Submission Log
A2: Date Added | B2: Card Description | C2: Year | D2: Set | E2: Parallel | F2: Raw Buy ($) | G2: PSA Tier | H2: PSA Fee ($) | I2: PSA 10 Avg ($) | J2: Target Price ($) | K2: Gem Rate (%) | L2: GO/NO-GO | M2: Est. Net ($) | N2: Est. ROI | O2: Date Submitted | P2: Status | Q2: Grade Returned | R2: Actual Sell ($) | S2: Actual Net ($) | T2: Actual ROI | U2: Notes
A3: 46113 | B3: 2024 Panini Prizm Patrick Mahomes RC Base #168 | C3: 2024 | D3: Panini Prizm | E3: Base Silver | F3: 18 | G3: Value Bulk | H3: 32.99 | I3: 120 | J3: =(F3+G3*H3)/(1-0.1325) | K3: 55 | L3: =IF(E3<40,"❌ NO-GO",IF(I3>=J3,"✅ GO","❌ NO-GO")) | M3: =I3*(1-0.1325)-H3-F3 | N3: =IF(F3>0,(M3/F3)*100,0) | P3: Queued
A4: 46117 | B4: 2023 Topps Chrome Corbin Carroll RC Auto #CPA-CC | C4: 2023 | D4: Bowman Chrome | E4: RC Auto | F4: 22 | G4: Value Bulk | H4: 32.99 | I4: 95 | J4: =(F4+G4*H4)/(1-0.1325) | K4: 48 | L4: =IF(E4<40,"❌ NO-GO",IF(I4>=J4,"✅ GO","❌ NO-GO")) | M4: =I4*(1-0.1325)-H4-F4 | N4: =IF(F4>0,(M4/F4)*100,0) | P4: Queued
A5: 46122 | B5: 2021 Panini Prizm LeBron James #129 Silver | C5: 2021 | D5: Panini Prizm | E5: Silver | F5: 25 | G5: Value Plus | H5: 49.99 | I5: 200 | J5: =(F5+G5*H5)/(1-0.1325) | K5: 62 | L5: =IF(E5<40,"❌ NO-GO",IF(I5>=J5,"✅ GO","❌ NO-GO")) | M5: =I5*(1-0.1325)-H5-F5 | N5: =IF(F5>0,(M5/F5)*100,0) | P5: Queued
A53: SUMMARY
A54: Total Cards: | B54: =COUNTA(A3:A51)
A55: Total Invested ($): | B55: =SUM(F3:F51)
A56: Total Est. Net ($): | B56: =SUM(M3:M51)
A57: Total Actual Net ($): | B57: =SUM(S3:S51)
A58: GO Decisions: | B58: =COUNTIF(L3:L51,"*GO*")-COUNTIF(L3:L51,"*NO-GO*")

Sheet Grading Candidates
A1: Grading Candidates — PSA Submission Shortlist
A2: Populate from the Inventory & Aging tab — cards you are considering submitting to PSA
A3: Rank | B3: Card Description | C3: Category | D3: Cost Basis ($) | E3: Gem Rate (%) | F3: Gem Signal | G3: PSA Tier | H3: Target Price ($) | I3: PSA 10 Est. ($) | J3: Est. Net ($) | K3: Est. ROI (%) | L3: Decision | M3: Notes
F4: 🟢 ≥60% | 🟡 40-59% | 🔴 <40% | L4: GO, NO-GO, HOLD, RESEARCH
